File: Observation of a Zero-Field Josephson Diode Effect in a Helimagnet Josephson Junction/Figure 1/Magnetic Characterization/CNS_KL180615_003_abplane_Hscan002.dat
[Header]
; MPMS3 Data File (default extension .dat)
; Copyright (c) 2007, Quantum Design, Inc. All rights reserved.
TITLE,CNS_KL180615_003_abplane_Hscan002
FILEOPENTIME,3740032898.89116,07/06/2018,10:03 am
BYAPP,SQUID AC,0.9.1.0
INFO,MPMS3 Measurement Release 1.1.16 Build 347, MultiVu Release 2.3.3.2,APPNAME
INFO,1,MOMENT_UNITS
INFO,CrNb3S6,SAMPLE_MATERIAL
INFO,KL180615_003,SAMPLE_COMMENT
INFO,,SAMPLE_MASS
INFO,,SAMPLE_VOLUME
INFO,,SAMPLE_MOLECULAR_WEIGHT
INFO,,SAMPLE_SIZE
INFO,powder,SAMPLE_SHAPE
INFO,Standard,SAMPLE_HOLDER
INFO,Standard,SAMPLE_HOLDER_DETAIL
INFO,67.15,SAMPLE_OFFSET
DATATYPE,COMMENT,1
DATATYPE,TIME,2
STARTUPAXIS,X,2
STARTUPAXIS,Y1,5
FIELDGROUP, VSM,2,3,4,5,6,8,9,10,11,14,15
FIELDGROUP, DC, 2,3,4,14,56,57,58,59,60,61,62,63,64,65,66,67,68,69
FIELDGROUP, AC, 2,3,4,11,16,17,18,19,20,21,22,23,24,25,26,27,28,29,30
STARTUPGROUP, All
[Data]
Comment,Time Stamp (sec),Temperature (K),Magnetic Field (Oe),Moment (Am2),M. Std. Err. (Am2),Transport Action,Averaging Time (sec),Frequency (Hz),Peak Amplitude (mm),Center Position (mm),Lockin Signal' (V),Lockin Signal (V),Range,M. Quad. Signal (Am2),AC Moment (Am2),AC M. Std Err. (Am2),AC Phase (deg),AC Phase Std. Err. (deg),AC Susceptibility (Am2/T),AC Suscept. Std Err. (Am2/T),AC X' (Am2/T),AC X' Std Err. (Am2/T),AC X'' (Am2/T),AC X'' Std Err. (Am2/T),AC Drive (T),AC Frequency (Hz),AC Averaging Time (sec),AC Cycles,AC Range,AC Measure Type,AC Signal' (V),AC Signal'' (V),AC Trim Coil Ratio,AC Trim Coil Phase,Min. Temperature (K),Max. Temperature (K),Min. Field (Oe),Max. Field (Oe),Mass (grams),Motor Lag (deg),Pressure (Torr),Measure Count,Measurement Number,SQUID Status (code),Motor Status (code),Measure Status (code),Motor Current (amps),Motor Temp. (C),Temp. Status (code),Field Status (code),Chamber Status (code),Chamber Temp (K),Redirection State,Evercool Status,Average Temp (K),Rotation Angle (deg),Rotator state,DC Moment Fixed Ctr (emu),DC Moment Err Fixed Ctr (emu),DC Moment Free Ctr (emu),DC Moment Err Free Ctr (emu),DC Fixed Fit,DC Free Fit,DC Calculated Center (mm),DC Calculated Center Err (mm),DC Scan Length (mm),DC Scan Time (s),DC Number of Points,DC Squid Drift,DC Min V (V),DC Max V (V),DC Scans per Measure,Map 01,Map 02,Map 03,Map 04,Map 05,Map 06,Map 07,Map 08,Map 09,Map 10,Map 11,Map 12,Map 13,Map 14,Map 15,Map 16
,3740032916.08846,2.00025928020477,0.237860232591629,,,6,,,,31.8006210327148,,,1,,,,,,,,,,,,,,,,,,,,,,1.99902665615082,2.00080442428589,0.170771449804306,0.317146956920624,,,3.11535096168518,-99999999,1,0,0,0,0,30.3030319213867,1,1,1,2.00041890144348,0,3154121952,1.99993730745008,,,-0.000271001300662496,1.35772342917458E-5,-0.000271170367403807,1.35775512075057E-5,0.905379414558411,0.911895275115967,31.6700248718262,0.189574882388115,30,4,200,0.0184495393186808,-0.513911068439484,0.921198904514313,1,,,,,,,,,,,,,,,,
,3740033078.10729,2.00020062923431,282.736526489258,,,6,,,,31.8006210327148,,,10,,,,,,,,,,,,,,,,,,,,,,1.99891626834869,2.00085377693176,271.84375,292.604675292969,,,3.17489242553711,-99999999,1,0,0,0,0,30.3030319213867,1,6,1,2.00037717819214,0,3154122048,2.00003762678667,,,0.00664546884223513,0.000331744285698365,0.00665095322824867,0.00033175543270473,0.957592129707336,0.9852574467659,31.6499423980713,0.188916072249413,30,4,200,0.491661936044693,-1.53964197635651,2.19469952583313,1,,,,,,,,,,,,,,,,
,3740033210.98248,2.00039863586426,548.62158203125,,,6,,,,31.8006210327148,,,10,,,,,,,,,,,,,,,,,,,,,,1.99907922744751,2.00079345703125,537.966674804687,558.325012207031,,,3.22036170959473,-99999999,1,0,0,0,0,30.3030319213867,1,6,1,2.00107479095459,0,3154122144,2.00000658902255,,,0.0106285667415634,0.000530602915077855,0.0106384097491571,0.000530624419703449,0.956676006317139,0.98958557844162,31.6413249969482,0.188926368951797,30,4,200,0.494695961475372,-3.14499068260193,2.34436297416687,1,,,,,,,,,,,,,,,,
,3740033343.78846,2.00049901008606,814.213897705078,,,6,,,,31.8006210327148,,,10,,,,,,,,,,,,,,,,,,,,,,1.99898266792297,2.00104403495789,803.418701171875,824.033264160156,,,3.2591712474823,-99999999,1,0,0,0,0.0139617919921875,30.3030319213867,1,6,1,2.00068211555481,0,3154121824,1.99998147921129,,,0.0147629902681598,0.000737010137720416,0.0147772532787923,0.000737043816083511,0.956453025341034,0.992371618747711,31.6381549835205,0.18894000351429,30,4,200,0.475495517253876,-4.82161569595337,2.56490612030029,1,,,,,,,,,,,,,,,,
,3740033487.39338,2.00024539232254,1100.65856933594,,,6,,,,31.8006210327148,,,100,,,,,,,,,,,,,,,,,,,,,,1.99874269962311,2.00076341629028,1089.80236816406,1110.30712890625,,,3.29946708679199,-99999999,1,0,0,0,0,30.3030319213867,1,6,1,2.00040197372437,0,3154122080,1.99994676763361,,,0.020387870537711,0.0010178675460412,0.0204085906195144,0.00101791821152759,0.95539778470993,0.992297470569611,31.6340847015381,0.188929811120033,30,4,200,0.046330776065588,-0.698066771030426,0.281144440174103,1,,,,,,,,,,,,,,,,
,3740033620.50758,2.00037097930908,1367.08032226562,,,6,,,,31.8006210327148,,,100,,,,,,,,,,,,,,,,,,,,,,1.99897801876068,2.00098896026611,1356.38879394531,1376.78381347656,,,3.33351469039917,-99999999,1,0,0,0,0,30.3030319213867,1,6,1,2.00056600570679,0,3154122080,1.9999683228406,,,0.0309673995901592,0.00154589243335219,0.0309930065274643,0.00154595084717434,0.957772850990295,0.985606968402863,31.6501522064209,0.188912749290466,30,4,200,0.0457747206091881,-1.1259503364563,0.337758123874664,1,,,,,,,,,,,,,,,,
,3740033753.71008,2.00049448013306,1633.39227294922,,,6,,,,31.8006210327148,,,100,,,,,,,,,,,,,,,,,,,,,,1.99885606765747,2.00095438957214,1622.4873046875,1643.4921875,,,3.36828207969666,-99999999,1,0,0,0,0.014801025390625,30.3030319213867,1,6,1,2.00065088272095,0,3154122176,2.0000083879991,,,0.0531252579205891,0.00265268794202137,0.0531884812545976,0.00265284744186561,0.952125549316406,0.993991851806641,31.6206359863281,0.188989296555519,30,4,200,0.0429780073463917,-1.99377536773682,0.452569097280502,1,,,,,,,,,,,,,,,,
,3740033886.97891,2.00046014785767,1899.84448242187,,,6,,,,31.8006210327148,,,100,,,,,,,,,,,,,,,,,,,,,,1.99886953830719,2.00104808807373,1889.037109375,1909.615234375,,,3.40106225013733,-99999999,1,0,0,0,0.0139617919921875,30.3030319213867,1,6,1,2.00083494186401,0,3154121888,2.00008152831684,,,0.0581895974169524,0.00290607559896704,0.05826993445453,0.00290626398935003,0.948590815067291,0.995908796787262,31.6064167022705,0.189017087221146,30,4,200,0.0422227904200554,-2.20759606361389,0.482852011919022,1,,,,,,,,,,,,,,,,
,3740034019.93902,2.00034117698669,2165.70520019531,,,6,,,,31.8006210327148,,,100,,,,,,,,,,,,,,,,,,,,,,1.99855995178223,2.00094270706177,2155.02587890625,2175.78686523438,,,3.43224930763245,-99999999,1,0,0,0,0.0148773193359375,30.3030319213867,1,6,1,2.00060367584229,0,3154121856,1.99997503107244,,,0.0586276293347743,0.00292795238448396,0.0587085586510423,0.00292814512952597,0.948596835136414,0.995693266391754,31.6064872741699,0.189025670289993,30,4,200,0.041433822363615,-2.22419714927673,0.481515675783157,1,,,,,,,,,,,,,,,,
,3740034153.23761,2.00026857852936,2432.51123046875,,,6,,,,31.8006210327148,,,100,,,,,,,,,,,,,,,,,,,,,,1.99852228164673,2.00080370903015,2421.64892578125,2442.27563476562,,,3.46350312232971,-99999999,1,0,0,0,0.0148773193359375,30.3030319213867,1,6,1,2.00050926208496,0,3154121856,1.99999316172166,,,0.0587813969781274,0.00293559852920134,0.0588616448967659,0.00293577953080843,0.948803901672363,0.995610475540161,31.6073169708252,0.189017102122307,30,4,200,0.0409026071429253,-2.23154950141907,0.480746001005173,1,,,,,,,,,,,,,,,,
,3740034298.23402,2.00042068958282,2319.41772460938,,,6,,,,31.8006210327148,,,100,,,,,,,,,,,,,,,,,,,,,,1.99857699871063,2.00097489356995,2309.24462890625,2330.3349609375,,,3.49526929855347,-99999999,1,0,0,0,0.0139617919921875,30.3030319213867,1,6,1,2.00083827972412,0,3154121952,2.00002894618294,,,0.0586956683859835,0.00293130627281191,0.0587755310555355,0.00293148015135965,0.948881149291992,0.996026337146759,31.6074848175049,0.189030259847641,30,4,200,-0.0472358018159866,-2.41884350776672,0.292245596647263,1,,,,,,,,,,,,,,,,
,3740034431.28872,2.00051176548004,2053.23992919922,,,6,,,,31.8006210327148,,,100,,,,,,,,,,,,,,,,,,,,,,1.99892342090607,2.00104641914368,2043.42687988281,2064.01684570313,,,3.52479076385498,-99999999,1,0,0,0,0.0139617919921875,30.3030319213867,1,6,1,2.00079274177551,0,3154122080,2.0000123760917,,,0.0585201384391869,0.00292251791794575,0.0585995581079208,0.00292270543051576,0.94903165102005,0.995871901512146,31.6080951690674,0.189037397503853,30,4,200,-0.0463567189872265,-2.41808795928955,0.290268510580063,1,,,,,,,,,,,,,,,,
,3740034564.69553,2.00010633468628,1786.46441650391,,,6,,,,31.8006210327148,,,100,,,,,,,,,,,,,,,,,,,,,,1.99917566776276,2.00104427337646,1776.18151855469,1797.24743652344,,,3.55201148986816,-99999999,1,0,0,0,0.012969970703125,30.3030319213867,1,6,1,2.00049161911011,0,3154122048,2.00009687380357,,,0.0580177257259957,0.00289738835872275,0.0580956289718802,0.00289757160652964,0.949295341968536,0.995869219303131,31.6091117858887,0.18902125954628,30,4,200,-0.0449029728770256,-2.38460326194763,0.295251965522766,1,,,,,,,,,,,,,,,,
,3740034697.61663,2.00051403045654,1520.68927001953,,,6,,,,31.8006210327148,,,100,,,,,,,,,,,,,,,,,,,,,,1.99896657466888,2.00091743469238,1510.76623535156,1531.60034179687,,,3.57079577445984,-99999999,1,0,0,0,0.0012969970703125,30.3030319213867,5,6,1,2.00066900253296,0,3154122112,1.99993881312284,,,0.0518068811064382,0.00258671871408337,0.0518651530259901,0.00258684720635265,0.953263223171234,0.993856549263,31.6250324249268,0.188989832997322,30,4,200,-0.0438795834779739,-2.14047408103943,0.256169557571411,1,,,,,,,,,,,,,,,,
,3740034831.19266,2.00038373470306,1253.37701416016,,,6,,,,31.8006210327148,,,100,,,,,,,,,,,,,,,,,,,,,,1.99836921691895,2.0011146068573,1243.24060058594,1264.28198242188,,,3.58356976509094,-99999999,1,0,0,0,0.0139617919921875,30.3030319213867,1,6,1,2.00065326690674,0,3154122048,1.99995177442377,,,0.0302087148487968,0.00150791286990842,0.03023225658952,0.0015079645784286,0.95947527885437,0.98758339881897,31.6543636322022,0.188954517245293,30,4,200,-0.0441425070166588,-1.29812240600586,0.126991644501686,1,,,,,,,,,,,,,,,,
,3740034964.52628,2.00033414363861,986.86376953125,,,6,,,,31.8006210327148,,,100,,,,,,,,,,,,,,,,,,,,,,1.99872124195099,2.00110530853271,976.971313476563,997.561401367187,,,3.5943021774292,-99999999,1,0,0,0,0.015716552734375,30.3030319213867,1,6,1,2.00092339515686,0,3154121984,2.00002598762512,,,0.0199872567595684,0.000997809931589027,0.0200061923887889,0.000997851324859382,0.956690192222595,0.991839528083801,31.6393985748291,0.188947409391403,30,4,200,-0.043285496532917,-0.887380182743073,0.07139752805233,1,,,,,,,,,,,,,,,,
,3740035097.49942,2.000648021698,721.527679443359,,,6,,,,31.8006210327148,,,100,,,,,,,,,,,,,,,,,,,,,,1.99870884418488,2.00097322463989,711.641235351562,732.231384277344,,,3.60939359664917,-99999999,1,0,0,0,0.0139617919921875,30.3030319213867,1,6,1,2.00084185600281,0,3154122080,1.99990624731237,,,0.0143913071171784,0.0007184109666382,0.0144040635872795,0.000718436784520967,0.957866430282593,0.99124401807785,31.6443862915039,0.188947916030884,30,4,200,-0.043099295347929,-0.666205585002899,0.0440371669828892,1,,,,,,,,,,,,,,,,
,3740035230.4876,2.00067055225372,455.569412231445,,,6,,,,31.8006210327148,,,100,,,,,,,,,,,,,,,,,,,,,,1.99844336509705,2.00099158287048,445.445129394531,466.510986328125,,,3.62634992599487,-99999999,1,0,0,0,0.0139617919921875,30.3030319213867,1,6,1,2.00064420700073,0,3154121824,1.99997645074671,,,0.00977370088317737,0.000487886842078687,0.00978192461913204,0.000487905590219505,0.958565831184387,0.989370346069336,31.6488227844238,0.188948288559914,30,4,200,-0.043076328933239,-0.486713230609894,0.0173259768635035,1,,,,,,,,,,,,,,,,
,3740035363.57942,2.00047159194946,189.202560424805,,,6,,,,31.8006210327148,,,100,,,,,,,,,,,,,,,,,,,,,,1.99854207038879,2.00098180770874,179.005065917969,199.997756958008,,,3.64173412322998,-99999999,1,0,0,0,0.016021728515625,30.3030319213867,1,6,1,2.00064849853516,0,3154121664,1.9999921430241,,,0.00530188693994028,0.000264675828650627,0.00530589023200247,0.000264684136953859,0.9572713971138,0.980492532253265,31.6565055847168,0.18895860016346,30,4,200,-0.0420366860926151,-0.312671691179276,-0.00201692525297403,1,,,,,,,,,,,,,,,,
,3740036796.71559,109.999877929688,26.5183651447296,,,6,,,,31.8006210327148,,,10,,,,,,,,,,,,,,,,,,,,,,109.998878479004,110.000793457031,4.85478830337524,46.9865417480469,,,10.8339595794678,-99999999,1,0,0,0,0.0139617919921875,30.3030319213867,1,6,1,109.999069213867,0,3154121888,110.000011989049,,,0.00124733545330294,6.2594534780509E-5,0.00124831526613863,6.25965220493324E-5,0.889529049396515,0.896490752696991,31.6539249420166,0.189953580498695,30,4,200,0.492720067501068,-0.253449410200119,4.86967849731445,1,,,,,,,,,,,,,,,,
,3740036934.57388,110.000019073486,302.326461791992,,,6,,,,31.8006210327148,,,10,,,,,,,,,,,,,,,,,,,,,,109.999702453613,110.001358032227,291.616668701172,312.231201171875,,,10.8787040710449,-99999999,1,0,0,0,0.0148773193359375,30.3030319213867,1,6,1,109.999862670898,0,3154122176,110.000556945801,,,0.00506942599376569,0.000252956181273955,0.00507123964490454,0.000252960334743033,0.96970146894455,0.984643042087555,31.7016448974609,0.188870504498482,30,4,200,0.489783704280853,-1.00386953353882,2.03253364562988,1,,,,,,,,,,,,,,,,
,3740037067.06333,110.000045776367,567.36376953125,,,6,,,,31.8006210327148,,,10,,,,,,,,,,,,,,,,,,,,,,109.999984741211,110.001007080078,556.434387207031,577.268493652344,,,10.9297218322754,-99999999,1,0,0,0,0.0139617919921875,30.3030319213867,1,6,1,110.00008392334,0,3154121952,110.000383550471,,,0.0084768040995461,0.000422936434137815,0.00847946511303486,0.000422942075238128,0.973219990730286,0.989212930202484,31.7077312469482,0.188853651285172,30,4,200,0.490947902202606,-2.32179522514343,2.20055413246155,1,,,,,,,,,,,,,,,,
,3740037200.2012,109.999473571777,833.541534423828,,,6,,,,31.8006210327148,,,10,,,,,,,,,,,,,,,,,,,,,,109.99919128418,110.000984191895,822.75244140625,843.525573730469,,,10.9656953811646,-99999999,1,0,0,0,0,30.3030319213867,1,6,1,109.999221801758,0,3154121952,110.000112360174,,,0.0130503186191304,0.000651132538124761,0.0130546791947145,0.000651141799279472,0.972752273082733,0.989851295948029,31.7047805786133,0.188880085945129,30,4,200,0.473629832267761,-4.11527824401855,2.46456027030945,1,,,,,,,,,,,,,,,,
,3740037343.86842,109.999393463135,1120.16918945312,,,6,,,,31.8006210327148,,,100,,,,,,,,,,,,,,,,,,,,,,109.998992919922,110.000411987305,1109.27038574219,1130.06787109375,,,11.0039920806885,-99999999,1,0,0,0,0.0139617919921875,30.3030319213867,1,6,1,109.999290466309,0,3154122048,109.999771118164,,,0.027563989894326,0.00137539279502796,0.0275745812486,0.00137542015665506,0.969842195510864,0.986533999443054,31.6983451843262,0.188883870840073,30,4,200,0.0470926836133003,-0.984830498695374,0.325502097606659,1,,,,,,,,,,,,,,,,
,3740037476.34803,109.999389648438,1385.34069824219,,,6,,,,31.8006210327148,,,100,,,,,,,,,,,,,,,,,,,,,,109.999229431152,110.000267028809,1374.55163574219,1395.05639648438,,,11.0481395721436,-99999999,1,0,0,0,0.0139617919921875,30.3030319213867,1,6,1,109.999549865723,0,3154121920,109.99981620095,,,0.0335421672646169,0.0016738825149225,0.0335617076905852,0.001673928700662,0.966288924217224,0.994758069515228,31.6744194030762,0.188896149396896,30,4,200,0.0434927344322205,-1.21683704853058,0.345013380050659,1,,,,,,,,,,,,,,,,
,3740037609.16217,109.999454498291,1650.798828125,,,6,,,,31.8006210327148,,,100,,,,,,,,,,,,,,,,,,,,,,109.999076843262,110.000755310059,1640.00366210938,1660.39868164062,,,11.0831079483032,-99999999,1,0,0,0,0.0139617919921875,30.3030319213867,1,6,1,109.999374389648,0,3154122144,109.999983354048,,,0.034863937616178,0.00173987683400326,0.0348850665059599,0.00173992802910688,0.965736508369446,0.995329320430756,31.671968460083,0.188907191157341,30,4,200,0.0421843603253365,-1.28305375576019,0.348218619823456,1,,,,,,,,,,,,,,,,
,3740037741.87651,109.999534606934,1916.15319824219,,,6,,,,31.8006210327148,,,100,,,,,,,,,,,,,,,,,,,,,,109.999473571777,110.000953674316,1905.32141113281,1926.20434570313,,,11.1295871734619,-99999999,1,0,0,0,0.0139617919921875,30.3030319213867,1,6,1,109.999565124512,0,3154121952,110.000133861195,,,0.0351096020351242,0.00175214816413955,0.0351311547250828,0.00175220063388845,0.965540170669556,0.995448529720306,31.67116355896,0.188897475600243,30,4,200,0.041397862136364,-1.29004669189453,0.337964355945587,1,,,,,,,,,,,,,,,,
,3740037875.04414,109.999401092529,2182.50183105469,,,6,,,,31.8006210327148,,,100,,,,,,,,,,,,,,,,,,,,,,109.999290466309,110.00074005127,2171.68823242187,2192.30297851562,,,11.1621656417847,-99999999,1,0,0,0,0.014495849609375,30.3030319213867,1,6,1,109.99951171875,0,3154121856,110.000006935813,,,0.0352440609539189,0.00175883142351367,0.0352651447005795,0.00175888374293775,0.965991795063019,0.995457589626312,31.6728935241699,0.188895434141159,30,4,200,0.0408810786902905,-1.29483950138092,0.34428209066391,1,,,,,,,,,,,,,,,,
,3740038008.02645,109.999641418457,2448.58801269531,,,6,,,,31.8006210327148,,,100,,,,,,,,,,,,,,,,,,,,,,109.999481201172,110.001037597656,2437.85986328125,2458.55981445313,,,11.1981010437012,-99999999,1,0,0,0,0.014801025390625,30.3030319213867,1,6,1,109.99974822998,0,3154121920,110.000153281472,,,0.0353477008729568,0.00176398847686329,0.0353683446003815,0.00176403467281876,0.966247081756592,0.995041310787201,31.6741027832031,0.188896581530571,30,4,200,0.0400934182107449,-1.31248950958252,0.342682093381882,1,,,,,,,,,,,,,,,,
,3740038153.53263,109.999912261963,2291.60034179687,,,6,,,,31.8006210327148,,,100,,,,,,,,,,,,,,,,,,,,,,109.999397277832,110.000801086426,2281.72607421875,2302.29174804687,,,11.247633934021,-99999999,1,0,0,0,0.0139617919921875,30.3030319213867,1,6,1,109.999702453613,0,3154121952,110.000114440918,,,0.0352701901063585,0.00176013593241237,0.0352912230051483,0.00176018098860979,0.965980768203735,0.995894253253937,31.6726665496826,0.188896730542183,30,4,200,-0.0478707477450371,-1.49067199230194,0.157809868454933,1,,,,,,,,,,,,,,,,
,3740038286.4585,109.999355316162,2025.73358154297,,,6,,,,31.8006210327148,,,100,,,,,,,,,,,,,,,,,,,,,,109.999252319336,110.00089263916,2016.01794433594,2036.66906738281,,,11.2826890945435,-99999999,1,0,0,0,0.0139617919921875,30.3030319213867,1,6,1,109.999320983887,0,3154122048,110.000027743253,,,0.0351526927288946,0.00175427198579833,0.0351736719218179,0.00175432003780314,0.965985417366028,0.995618879795074,31.6727905273438,0.18891330063343,30,4,200,-0.0467998422682285,-1.48082602024078,0.157089248299599,1,,,,,,,,,,,,,,,,
,3740038419.18215,109.999824523926,1760.34265136719,,,6,,,,31.8006210327148,,,100,,,,,,,,,,,,,,,,,,,,,,109.999382019043,110.001068115234,1750.33410644531,1771.16833496094,,,11.3303661346436,-99999999,1,0,0,0,0.0139617919921875,30.3030319213867,1,6,1,109.999717712402,0,3154121920,110.000177556818,,,0.034983997641845,0.00174584883000505,0.0350048477622868,0.00174590061373819,0.966058433055878,0.995484530925751,31.6731433868408,0.188915491104126,30,4,200,-0.044986467808485,-1.46954703330994,0.156899452209473,1,,,,,,,,,,,,,,,,
,3740038552.09887,109.999431610107,1494.59777832031,,,6,,,,31.8006210327148,,,100,,,,,,,,,,,,,,,,,,,,,,109.999000549316,110.001136779785,1485.02844238281,1505.59423828125,,,11.3772249221802,-99999999,1,0,0,0,0,30.3030319213867,1,6,1,109.998962402344,0,3154121984,110.000196977095,,,0.0347608722201335,0.00173472722303017,0.0347817673894878,0.00173477459371037,0.965840637683868,0.995495140552521,31.672290802002,0.188914865255356,30,4,200,-0.0433166585862637,-1.46253728866577,0.154949188232422,1,,,,,,,,,,,,,,,,
,3740038685.41803,109.999462127686,1227.79180908203,,,6,,,,31.8006210327148,,,100,,,,,,,,,,,,,,,,,,,,,,109.99934387207,110.001052856445,1217.85656738281,1238.54431152344,,,11.4012422561646,-99999999,1,0,0,0,0.0139617919921875,30.3030319213867,1,6,1,109.999450683594,0,3154121632,110.000223333185,,,0.0327823148647826,0.00163580403235736,0.0327982309767132,0.00163585169393777,0.969302356243134,0.994497418403625,31.6861686706543,0.188886910676956,30,4,200,-0.0432280637323856,-1.38509130477905,0.143632665276527,1,,,,,,,,,,,,,,,,
,3740038818.10902,109.999294281006,962.400817871094,,,6,,,,31.8006210327148,,,100,,,,,,,,,,,,,,,,,,,,,,109.998710632324,110.000877380371,952.319152832031,973.214294433594,,,11.4278955459595,-99999999,1,0,0,0,0.0148773193359375,30.3030319213867,1,6,1,109.998962402344,0,3154122016,109.999857815829,,,0.0199770490190301,0.000996665426096533,0.0199807590247248,0.000996675315985108,0.975443959236145,0.984138011932373,31.7295684814453,0.188844159245491,30,4,200,-0.0438850447535515,-0.890113174915314,0.0761284977197647,1,,,,,,,,,,,,,,,,
,3740038951.1093,109.998672485352,697.028076171875,,,6,,,,31.8006210327148,,,100,,,,,,,,,,,,,,,,,,,,,,109.998092651367,110.000366210938,687.196472167969,707.8232421875,,,11.4642143249512,-99999999,1,0,0,0,0.0139617919921875,30.3030319213867,1,6,1,109.998291015625,0,3154121920,109.999197526412,,,0.0112413208424057,0.000560838284901458,0.0112443329240176,0.00056084639500819,0.97522896528244,0.989661514759064,31.7153205871582,0.188848495483398,30,4,200,-0.0433541089296341,-0.542666494846344,0.0297446418553591,1,,,,,,,,,,,,,,,,
,3740039084.67514,109.9997215271,429.923202514648,,,6,,,,31.8006210327148,,,100,,,,,,,,,,,,,,,,,,,,,,109.999633789062,110.001304626465,420.000183105469,440.846466064453,,,11.5036706924438,-99999999,1,0,0,0,0,30.3030319213867,1,6,1,109.999755859375,0,3154121856,110.000418229537,,,0.00692231290350761,0.000345371959612501,0.0069241081111679,0.000345376688725514,0.973824620246887,0.986066341400146,31.7165985107422,0.188865765929222,30,4,200,-0.04322449862957,-0.372162997722626,0.0034555122256279,1,,,,,,,,,,,,,,,,
,3740039217.44055,109.999412536621,164.367515563965,,,6,,,,31.8006210327148,,,100,,,,,,,,,,,,,,,,,,,,,,109.999229431152,110.000625610352,154.499359130859,175.248092651367,,,11.5401954650879,-99999999,1,0,0,0,0.015869140625,30.3030319213867,1,6,1,109.999298095703,0,3154122016,109.999916770241,,,0.00337316037097509,0.000168327028483348,0.00337401636799972,0.000168329213142561,0.967474281787872,0.975983321666718,31.7174816131592,0.188892304897308,30,4,200,-0.0418059974908829,-0.23043230175972,-0.00660394504666328,1,,,,,,,,,,,,,,,,
,3740040124.32546,119.998966217041,59.7456111907959,,,6,,,,31.8006210327148,,,10,,,,,,,,,,,,,,,,,,,,,,119.998733520508,120.000015258789,48.8528327941895,69.6869506835938,,,11.7770738601685,-99999999,1,0,0,0,0.0139617919921875,30.3030319213867,1,6,1,119.998863220215,0,3154121856,119.999386180531,,,0.00156151857877531,7.80554961126299E-5,0.00156173091342351,7.80557822420068E-5,0.933264017105103,0.935268044471741,31.7389602661133,0.189188852906227,30,4,200,0.493800759315491,0.0577529035508633,2.09286785125732,1,,,,,,,,,,,,,,,,
,3740040257.08682,119.998931884766,325.215942382812,,,6,,,,31.8006210327148,,,10,,,,,,,,,,,,,,,,,,,,,,119.998809814453,120.000381469727,314.414642333984,335.187774658203,,,11.8137254714966,-99999999,1,0,0,0,0,30.3030319213867,1,6,1,119.998985290527,0,3154122240,119.999585931951,,,0.00496950576819266,0.000247944185703684,0.00497059332183117,0.000247946023649456,0.97339004278183,0.983103752136231,31.7227344512939,0.188819512724876,30,4,200,0.489745944738388,-0.978430569171906,2.0159707069397,1,,,,,,,,,,,,,,,,
,3740040390.09888,119.9993019104,591.332763671875,,,6,,,,31.8006210327148,,,10,,,,,,,,,,,,,,,,,,,,,,119.999130249023,120.000640869141,580.440002441406,601.310668945313,,,11.8471994400024,-99999999,1,0,0,0,0.00213623046875,30.3030319213867,1,6,1,119.999229431152,0,3154122048,119.999884865501,,,0.00858030996131808,0.000428077334286639,0.00858238295693798,0.000428081993309346,0.975326180458069,0.987850904464722,31.7192325592041,0.188867077231407,30,4,200,0.487735390663147,-2.34179139137268,2.28206467628479,1,,,,,,,,,,,,,,,,
,3740040534.0152,120.000110626221,878.832580566406,,,6,,,,31.8006210327148,,,100,,,,,,,,,,,,,,,,,,,,,,119.999847412109,120.001457214355,868.263061523437,888.231018066406,,,11.8737344741821,-99999999,1,0,0,0,0.015716552734375,30.3030319213867,1,6,1,120.000373840332,0,3154121920,120.000687339089,,,0.0182303498161489,0.000909585070706207,0.0182337960793862,0.000909594604359422,0.972755253314972,0.980368494987488,31.728982925415,0.188895225524902,30,4,200,0.0480005741119385,-0.62735253572464,0.267310172319412,1,,,,,,,,,,,,,,,,
,3740040666.70326,119.999710083008,1143.85150146484,,,6,,,,31.8006210327148,,,100,,,,,,,,,,,,,,,,,,,,,,119.999565124512,120.000587463379,1133.16613769531,1153.60986328125,,,11.9041261672974,-99999999,1,0,0,0,0.0148773193359375,30.3030319213867,1,6,1,119.999855041504,0,3154122112,120.00003675981,,,0.0268541329072192,0.00133997743475151,0.0268667391213879,0.00134000651422322,0.96970808506012,0.995227217674255,31.6872634887695,0.188888043165207,30,4,200,0.0458356030285358,-0.961080610752106,0.315475463867188,1,,,,,,,,,,,,,,,,
,3740040799.33912,119.99938583374,1409.32800292969,,,6,,,,31.8006210327148,,,100,,,,,,,,,,,,,,,,,,,,,,119.999290466309,120.000732421875,1398.43518066406,1418.72033691406,,,11.9336099624634,-99999999,1,0,0,0,0.0139617919921875,30.3030319213867,1,6,1,119.999374389648,0,3154122144,120.000037453391,,,0.0283405489735657,0.00141423680069032,0.028355830735438,0.00141427193594062,0.967678546905518,0.995905995368958,31.6791248321533,0.18888808786869,30,4,200,0.0435571484267712,-1.02047109603882,0.314753979444504,1,,,,,,,,,,,,,,,,
,3740040932.58043,119.999610900879,1675.63995361328,,,6,,,,31.8006210327148,,,100,,,,,,,,,,,,,,,,,,,,,,119.999328613281,120.000923156738,1664.716796875,1685.5751953125,,,11.9591732025146,-99999999,1,0,0,0,0.0139617919921875,30.3030319213867,1,6,1,119.999893188477,0,3154122048,120.000072826039,,,0.0285833418237217,0.00142631225121677,0.0285978972971396,0.00142634594794381,0.968569040298462,0.995823323726654,31.682580947876,0.18886511027813,30,4,200,0.042093500494957,-1.036576628685,0.30666595697403,1,,,,,,,,,,,,,,,,
,3740041065.80788,119.998725891113,1942.11053466797,,,6,,,,31.8006210327148,,,100,,,,,,,,,,,,,,,,,,,,,,119.998580932617,120.000045776367,1931.3154296875,1951.72241210938,,,11.9902725219727,-99999999,1,0,0,0,0.0139617919921875,30.3030319213867,1,6,1,119.998794555664,0,3154121920,119.99929670854,,,0.028818124674332,0.00143802570253321,0.0288326504853038,0.00143805899643914,0.968620181083679,0.99513840675354,31.6831378936768,0.188869670033455,30,4,200,0.0413397736847401,-1.05212616920471,0.307189673185348,1,,,,,,,,,,,,,,,,
,3740041198.28633,119.999801635742,2207.068359375,,,6,,,,31.8006210327148,,,100,,,,,,,,,,,,,,,,,,,,,,119.99967956543,120.00129699707,2196.26708984375,2216.89379882813,,,12.0323667526245,-99999999,1,0,0,0,0.014801025390625,30.3030319213867,1,6,1,119.999923706055,0,3154121920,120.000443892045,,,0.0289838225235663,0.00144625000344866,0.0289974094358321,0.00144628140010348,0.969602942466736,0.994477987289429,31.6873226165771,0.188871324062347,30,4,200,0.0408903062343597,-1.04908418655396,0.311172693967819,1,,,,,,,,,,,,,,,,
,3740041331.10985,119.998748779297,2472.82543945313,,,6,,,,31.8006210327148,,,100,,,,,,,,,,,,,,,,,,,,,,119.998626708984,120.000358581543,2461.7314453125,2482.72412109375,,,12.0809717178345,-99999999,1,0,0,0,0.015869140625,30.3030319213867,1,6,1,119.998756408691,0,3154121952,119.999425021085,,,0.029116828659871,0.00145290624876276,0.0291309557092873,0.00145293765445199,0.969175040721893,0.995129108428955,31.685266494751,0.188880443572998,30,4,200,0.0403392165899277,-1.06176722049713,0.30621936917305,1,,,,,,,,,,,,,,,,
,3740041476.49804,119.999561309814,2270.08312988281,,,6,,,,31.8006210327148,,,100,,,,,,,,,,,,,,,,,,,,,,119.999519348145,120.001388549805,2260.1845703125,2280.99438476562,,,12.1233005523682,-99999999,1,0,0,0,0.01495361328125,30.3030319213867,1,6,1,119.999603271484,0,3154121952,120.000476490368,,,0.0289730058029799,0.0014457588972316,0.0289877800070142,0.00144579118413644,0.968511164188385,0.995864450931549,31.6823310852051,0.188895702362061,30,4,200,-0.0477961339056492,-1.23846745491028,0.123188063502312,1,,,,,,,,,,,,,,,,
,3740041609.52814,120.000343322754,2004.0029296875,,,6,,,,31.8006210327148,,,100,,,,,,,,,,,,,,,,,,,,,,120.000282287598,120.001640319824,1994.02502441406,2014.90795898438,,,12.1509704589844,-99999999,1,0,0,0,0,30.3030319213867,1,6,1,120.00032043457,0,3154121824,120.000905123624,,,0.0288486379226826,0.00143952957124606,0.0288627984433798,0.00143956280426019,0.969047427177429,0.99518096446991,31.6847724914551,0.188867926597595,30,4,200,-0.0463305115699768,-1.23826861381531,0.126469701528549,1,,,,,,,,,,,,,,,,
,3740041742.35098,119.999248504639,1738.33142089844,,,6,,,,31.8006210327148,,,100,,,,,,,,,,,,,,,,,,,,,,119.99910736084,120.00057220459,1728.46325683594,1749.23645019531,,,12.1825876235962,-99999999,1,0,0,0,0.0140380859375,30.3030319213867,1,6,1,119.999313354492,0,3154121920,119.99984255704,,,0.0286405331750518,0.00142915370387206,0.028654771933863,0.00142918637372584,0.968850374221802,0.99526435136795,31.6839599609375,0.188883185386658,30,4,200,-0.0452162027359009,-1.23011374473572,0.124410077929497,1,,,,,,,,,,,,,,,,
,3740041875.22024,119.999485015869,1472.76348876953,,,6,,,,31.8006210327148,,,100,,,,,,,,,,,,,,,,,,,,,,119.999366760254,120.001220703125,1463.14538574219,1483.57702636719,,,12.2233772277832,-99999999,1,0,0,0,0,30.3030319213867,1,6,1,119.999603271484,0,3154121792,120.000342629173,,,0.02842784447322,0.00141855008171903,0.028442194039554,0.00141858237184641,0.96863603591919,0.995481073856354,31.683012008667,0.188885673880577,30,4,200,-0.0433696620166302,-1.21587228775024,0.116223976016045,1,,,,,,,,,,,,,,,,
,3740042008.23467,119.999546051025,1206.60394287109,,,6,,,,31.8006210327148,,,100,,,,,,,,,,,,,,,,,,,,,,119.99919128418,120.001129150391,1196.91271972656,1217.47839355469,,,12.2481088638306,-99999999,1,0,0,0,0.0139617919921875,30.3030319213867,1,6,1,119.99925994873,0,3154122080,120.000217090953,,,0.0279196945584948,0.00139316506422267,0.027933185326998,0.00139319594491701,0.969288229942322,0.995328485965729,31.6855964660645,0.188882037997246,30,4,200,-0.0430911332368851,-1.18947434425354,0.118729755282402,1,,,,,,,,,,,,,,,,
,3740042141.21125,119.999897003174,940.664031982422,,,6,,,,31.8006210327148,,,100,,,,,,,,,,,,,,,,,,,,,,119.999465942383,120.001457214355,930.777587890625,951.562927246094,,,12.2894124984741,-99999999,1,0,0,0,0.0139617919921875,30.3030319213867,1,6,1,119.999641418457,0,3154122080,120.000443892045,,,0.0234245476765074,0.00116866796422961,0.0234302091466421,0.00116868227004765,0.975258350372314,0.987611055374146,31.71946144104,0.188838824629784,30,4,200,-0.0435022078454494,-1.02447295188904,0.0934763178229332,1,,,,,,,,,,,,,,,,
,3740042273.77714,119.999507904053,676.029266357422,,,6,,,,31.8006210327148,,,100,,,,,,,,,,,,,,,,,,,,,,119.999252319336,120.000869750977,666.350219726563,686.903747558594,,,12.3201627731323,-99999999,1,0,0,0,0.0139617919921875,30.3030319213867,1,6,1,119.999412536621,0,3154121920,119.999969482422,,,0.0108905012713887,0.000543313966469944,0.0108925041709653,0.000543319122499478,0.976874887943268,0.986358761787415,31.7298450469971,0.188852369785309,30,4,200,-0.043329481035471,-0.523499608039856,0.0303209628909826,1,,,,,,,,,,,,,,,,
,3740042406.89044,119.999263763428,409.766098022461,,,6,,,,31.8006210327148,,,100,,,,,,,,,,,,,,,,,,,,,,119.9990234375,120.00074005127,400.068725585937,420.475891113281,,,12.3415832519531,-99999999,1,0,0,0,0.0140380859375,30.3030319213867,1,6,1,119.999061584473,0,3154121984,119.999891801314,,,0.00625916363130275,0.000312279990991113,0.00626056802663228,0.000312283204161274,0.974528908729553,0.985139191150665,31.7222232818604,0.188854575157166,30,4,200,-0.0430663302540779,-0.345024138689041,0.00441203219816089,1,,,,,,,,,,,,,,,,
,3740042540.13672,119.998847961426,143.411422729492,,,6,,,,31.8006210327148,,,100,,,,,,,,,,,,,,,,,,,,,,119.998359680176,120.000259399414,133.604263305664,154.231018066406,,,12.3813905715942,-99999999,1,0,0,0,0.0150299072265625,30.3030319213867,1,6,1,119.998481750488,0,3154122016,119.999376470392,,,0.00279412997213699,0.000139441129444257,0.00279458666913522,0.000139442098298242,0.965584576129913,0.970474243164062,31.7336006164551,0.188930928707123,30,4,200,-0.0419084019958973,-0.203661575913429,-0.00400349078699946,1,,,,,,,,,,,,,,,,
,3740043449.06392,129.99877166748,81.7934265136719,,,6,,,,31.8006210327148,,,10,,,,,,,,,,,,,,,,,,,,,,129.998474121094,130.000289916992,70.9799346923828,91.753059387207,,,12.6485891342163,-99999999,1,0,0,0,0.0139617919921875,30.3030319213867,1,6,1,129.998504638672,0,3154122112,129.999554720792,,,0.00163275732158455,8.1528391597192E-5,0.00163296939216912,8.15289184018913E-5,0.952032566070557,0.954672455787659,31.7411460876465,0.188991770148277,30,4,200,0.492320418357849,0.0614972338080406,2.08576512336731,1,,,,,,,,,,,,,,,,
,3740043582.17348,129.998542785645,348.032211303711,,,6,,,,31.8006210327148,,,10,,,,,,,,,,,,,,,,,,,,,,129.998489379883,130.000534057617,337.115020751953,357.741790771484,,,12.6944875717163,-99999999,1,0,0,0,0.0139617919921875,30.3030319213867,1,6,1,129.998596191406,0,3154121984,129.99958523837,,,0.00520735461339465,0.000259812258331727,0.00520831144758551,0.000259814776406718,0.973250687122345,0.980826079845428,31.7299461364746,0.188866257667542,30,4,200,0.495544821023941,-0.957181632518768,2.15930271148682,1,,,,,,,,,,,,,,,,
,3740043715.33909,129.999481201172,614.405151367187,,,6,,,,31.8006210327148,,,10,,,,,,,,,,,,,,,,,,,,,,129.998886108398,130.001129150391,603.591674804687,624.267211914062,,,12.7330665588379,-99999999,1,0,0,0,0.0019073486328125,30.3030319213867,1,6,1,129.999008178711,0,3154122112,130.000188654119,,,0.0138945191264337,0.000693270149804245,0.0138995106975305,0.000693284373646882,0.971863508224487,0.989293038845062,31.7020053863525,0.188872024416924,30,4,200,0.488437354564667,-4.4338526725769,2.51260042190552,1,,,,,,,,,,,,,,,,
,3740043859.0562,129.999473571777,901.246307373047,,,6,,,,31.8006210327148,,,100,,,,,,,,,,,,,,,,,,,,,,129.999084472656,130.001190185547,890.34130859375,910.931457519531,,,12.7805862426758,-99999999,1,0,0,0,0,30.3030319213867,1,6,1,129.999160766602,0,3154122144,130.000178943981,,,0.0165543285422224,0.000826016563738336,0.0165617125176765,0.000826034022937044,0.970407366752625,0.994853317737579,31.6902008056641,0.188878014683723,30,4,200,0.0471627786755562,-0.551229357719421,0.259402573108673,1,,,,,,,,,,,,,,,,
,3740043991.77747,129.999557495117,1166.50921630859,,,6,,,,31.8006210327148,,,100,,,,,,,,,,,,,,,,,,,,,,129.99951171875,130.001266479492,1155.62255859375,1176.57861328125,,,12.8077096939087,-99999999,1,0,0,0,0,30.3030319213867,1,6,1,129.999603271484,0,3154121984,130.000380082564,,,0.0172690482526952,0.00086166288311888,0.0172763967443992,0.000861680181859963,0.971059024333954,0.994784116744995,31.6927165985107,0.188878148794174,30,4,200,0.0454895682632923,-0.579430520534515,0.255310654640198,1,,,,,,,,,,,,,,,,
,3740044125.09078,129.998947143555,1433.32135009766,,,6,,,,31.8006210327148,,,100,,,,,,,,,,,,,,,,,,,,,,129.998901367188,130.000961303711,1422.34313964844,1443.49450683594,,,12.8598489761353,-99999999,1,0,0,0,0.014801025390625,30.3030319213867,1,6,1,129.998947143555,0,3154122080,129.999836314808,,,0.0178351307302042,0.000889966565662109,0.017843967034302,0.000889987228200735,0.968888163566589,0.995080173015594,31.6841907501221,0.188879147171974,30,4,200,0.0437152236700058,-0.606212794780731,0.251545339822769,1,,,,,,,,,,,,,,,,
,3740044258.10827,129.998992919922,1699.36492919922,,,6,,,,31.8006210327148,,,100,,,,,,,,,,,,,,,,,,,,,,129.99885559082,130.000396728516,1688.66125488281,1708.83666992187,,,12.9064855575562,-99999999,1,0,0,0,0.0139617919921875,30.3030319213867,1,6,1,129.998977661133,0,3154121888,129.999686501243,,,0.0183353966005621,0.000914868486591738,0.0183431329328802,0.000914885543551947,0.971107602119446,0.994641184806824,31.6930046081543,0.188881158828735,30,4,200,0.0415522903203964,-0.639926731586456,0.252865493297577,1,,,,,,,,,,,,,,,,
,3740044391.15398,129.999649047852,1965.54278564453,,,6,,,,31.8006210327148,,,100,,,,,,,,,,,,,,,,,,,,,,129.999450683594,130.001251220703,1954.62561035156,1975.24011230469,,,12.9324111938477,-99999999,1,0,0,0,0.0139617919921875,30.3030319213867,1,6,1,129.999633789062,0,3154121920,130.00029407848,,,0.0187720775358956,0.000936674484163135,0.0187803981886108,0.000936693799391621,0.970469832420349,0.994769692420959,31.690465927124,0.188878551125526,30,4,200,0.04133715108037,-0.651009798049927,0.252833694219589,1,,,,,,,,,,,,,,,,
,3740044524.42796,129.999443054199,2232.08032226562,,,6,,,,31.8006210327148,,,100,,,,,,,,,,,,,,,,,,,,,,129.99919128418,130.000793457031,2221.24853515625,2241.94848632813,,,12.964656829834,-99999999,1,0,0,0,0,30.3030319213867,1,6,1,129.999435424805,0,3154121952,129.999956997958,,,0.0191479572601647,0.000955425765783595,0.0191563586476985,0.00095544541200085,0.970612525939941,0.994728446006775,31.6910667419434,0.188872009515762,30,4,200,0.0404979065060616,-0.670323610305786,0.253759980201721,1,,,,,,,,,,,,,,,,
,3740044657.16779,129.99910736084,2493.50708007813,,,6,,,,31.8006210327148,,,100,,,,,,,,,,,,,,,,,,,,,,129.99870300293,130.000869750977,2486.70068359375,2500.38671875,,,12.9950561523437,-99999999,1,0,0,0,0.0139617919921875,30.3030319213867,1,6,1,129.998809814453,0,3154121856,129.999809958718,,,0.0194889950454265,0.000976079785279725,0.0195151917539343,0.000976137723203988,0.908917963504791,0.924196779727936,31.6086692810059,0.189572408795357,30,4,200,0.018740413710475,-0.737530469894409,0.244965776801109,1,,,,,,,,,,,,,,,,
,3740044801.863,129.999900817871,2253.64025878906,,,6,,,,31.8006210327148,,,100,,,,,,,,,,,,,,,,,,,,,,129.99967956543,130.001098632812,2243.71728515625,2264.5634765625,,,13.0452909469604,-99999999,1,0,0,0,0.01678466796875,30.3030319213867,1,6,1,129.999923706055,0,3154121824,130.000327370384,,,0.0191605973262146,0.000956052344268899,0.0191689154392568,0.000956071526760357,0.970778524875641,0.994869291782379,31.6916236877441,0.18887098133564,30,4,200,-0.0481662079691887,-0.861436069011688,0.0687736943364143,1,,,,,,,,,,,,,,,,
,3740044934.64688,129.999549865723,1988.02972412109,,,6,,,,31.8006210327148,,,100,,,,,,,,,,,,,,,,,,,,,,129.999374389648,130.00048828125,1978.14331054687,1998.708984375,,,13.0754699707031,-99999999,1,0,0,0,0.01617431640625,30.3030319213867,1,6,1,129.999496459961,0,3154122176,129.999908447266,,,0.0187793701809854,0.000937024980570217,0.0187873804241414,0.000937043354993491,0.970963716506958,0.994543790817261,31.692590713501,0.188847586512566,30,4,200,-0.0469492040574551,-0.842535555362701,0.0677433386445046,1,,,,,,,,,,,,,,,,
,3740045067.77345,129.998924255371,1721.80914306641,,,6,,,,31.8006210327148,,,100,,,,,,,,,,,,,,,,,,,,,,129.998794555664,130.000610351562,1712.05700683594,1732.62268066406,,,13.1137990951538,-99999999,1,0,0,0,0,30.3030319213867,1,6,1,129.999069213867,0,3154122016,129.999646273526,,,0.018355809955749,0.000915898910305371,0.0183637896282901,0.000915918306824048,0.970658898353577,0.994137465953827,31.6917190551758,0.188842222094536,30,4,200,-0.0452561974525452,-0.822573482990265,0.0667007565498352,1,,,,,,,,,,,,,,,,
,3740045200.19117,129.999176025391,1457.03424072266,,,6,,,,31.8006210327148,,,100,,,,,,,,,,,,,,,,,,,,,,129.998992919922,130.000534057617,1447.01965332031,1467.81726074219,,,13.1549282073975,-99999999,1,0,0,0,0.014801025390625,30.3030319213867,1,6,1,129.999359130859,0,3154122080,129.999809958718,,,0.0178801551890082,0.00089217606084827,0.0178881229075382,0.000892194120761146,0.970237553119659,0.994029760360718,31.6901626586914,0.188853666186333,30,4,200,-0.0435775220394135,-0.79545247554779,0.0680441856384277,1,,,,,,,,,,,,,,,,
,3740045332.83015,129.999534606934,1191.60046386719,,,6,,,,31.8006210327148,,,100,,,,,,,,,,,,,,,,,,,,,,129.999359130859,130.000946044922,1181.76281738281,1202.42614746094,,,13.1904878616333,-99999999,1,0,0,0,0.015869140625,30.3030319213867,1,6,1,129.999526977539,0,3154122144,130.000152587891,,,0.0173024799805189,0.000863347415034809,0.0173101619963482,0.000863366203043279,0.970393240451813,0.994281947612762,31.6905632019043,0.188867121934891,30,4,200,-0.0432426743209362,-0.780236303806305,0.0555649921298027,1,,,,,,,,,,,,,,,,
,3740045466.10822,129.999076843262,925.068939208984,,,6,,,,31.8006210327148,,,100,,,,,,,,,,,,,,,,,,,,,,129.998779296875,130.000518798828,915.34716796875,935.839721679688,,,13.215989112854,-99999999,1,0,0,0,0.0148773193359375,30.3030319213867,1,6,1,129.999008178711,0,3154122080,129.999676791104,,,0.0166051762838309,0.000828560450727883,0.0166125728717798,0.000828578580040239,0.970138430595398,0.993277490139008,31.6903762817383,0.188859269022942,30,4,200,-0.043138325214386,-0.748807668685913,0.0564743094146252,1,,,,,,,,,,,,,,,,
,3740045599.03992,129.998725891113,659.885284423828,,,6,,,,31.8006210327148,,,100,,,,,,,,,,,,,,,,,,,,,,129.998489379883,130.000961303711,650.322082519531,670.656066894531,,,13.2415628433228,-99999999,1,0,0,0,0.014801025390625,30.3030319213867,1,6,1,129.998626708984,0,3154121824,129.999601884322,,,0.0148735966622092,0.000742165711511162,0.0148801031450891,0.000742182051817992,0.969811975955963,0.990997135639191,31.6914443969727,0.188867226243019,30,4,200,-0.043086227029562,-0.679185032844543,0.0505209974944592,1,,,,,,,,,,,,,,,,
,3740045732.0088,129.999214172363,393.823364257812,,,6,,,,31.8006210327148,,,100,,,,,,,,,,,,,,,,,,,,,,129.999038696289,130.001007080078,383.857635498047,404.630767822266,,,13.2781648635864,-99999999,1,0,0,0,0,30.3030319213867,1,6,1,129.999099731445,0,3154121984,129.999955610795,,,0.00606332644519372,0.000302494912035669,0.00606424454946293,0.000302497259402989,0.976473808288574,0.983681201934814,31.7364063262939,0.188823655247688,30,4,200,-0.042982567101717,-0.33650153875351,0.00471964990720153,1,,,,,,,,,,,,,,,,
,3740045864.97787,129.999801635742,127.913909912109,,,6,,,,31.8006210327148,,,100,,,,,,,,,,,,,,,,,,,,,,129.999359130859,130.001113891602,118.07625579834,138.788391113281,,,13.3082790374756,-99999999,1,0,0,0,0,30.3030319213867,1,6,1,129.999710083008,0,3154121856,130.000377308239,,,0.00224981203311194,0.000112297516504373,0.00225034002929831,0.000112298743938944,0.96062159538269,0.966776549816132,31.7205715179443,0.188928663730621,30,4,200,-0.0416856519877911,-0.182193964719772,-0.00645554903894663,1,,,,,,,,,,,,,,,,
,3740046795.64754,139.998748779297,104.701198577881,,,6,,,,31.8006210327148,,,10,,,,,,,,,,,,,,,,,,,,,,139.998565673828,139.999893188477,93.7779235839844,114.636436462402,,,13.5786228179932,-99999999,1,0,0,0,0.0139617919921875,30.3030319213867,1,6,1,139.998947143555,0,3154122176,139.999271739613,,,0.000270795802834982,1.35774007809017E-5,0.000270798875573629,1.35774062563244E-5,0.897627174854279,0.897732973098755,31.8183364868164,0.189788728952408,30,4,200,0.489285707473755,0.120553195476532,2.13221979141235,1,,,,,,,,,,,,,,,,
,3740046928.87839,139.999794006348,371.196136474609,,,6,,,,31.8006210327148,,,10,,,,,,,,,,,,,,,,,,,,,,139.999465942383,140.000640869141,360.388732910156,381.222869873047,,,13.6186876296997,-99999999,1,0,0,0,0.015716552734375,30.3030319213867,1,6,1,139.99983215332,0,3154122048,140.000116521662,,,0.00100031462263385,4.99626887672974E-5,0.00100109376742788,4.99642033369925E-5,0.946513533592224,0.963021576404572,31.6538143157959,0.189057230949402,30,4,200,0.493055999279022,0.0460862778127193,2.04699850082397,1,,,,,,,,,,,,,,,,
,3740047061.95535,139.998580932617,637.483703613281,,,6,,,,31.8006210327148,,,10,,,,,,,,,,,,,,,,,,,,,,139.998229980469,140.00065612793,626.670227050781,647.126159667969,,,13.6429176330566,-99999999,1,0,0,0,7.62939453125E-5,30.3030319213867,1,6,1,139.998931884766,0,3154122016,139.999579689719,,,0.00173058380296868,8.6361829935449E-5,0.00173140570104202,8.6363492323797E-5,0.966604471206665,0.985691487789154,31.6865081787109,0.188875690102577,30,4,200,0.481372863054276,0.0293512903153896,1.9834246635437,1,,,,,,,,,,,,,,,,
,3740047194.7287,139.998489379883,902.478332519531,,,6,,,,31.8006210327148,,,10,,,,,,,,,,,,,,,,,,,,,,139.998001098633,140.000366210938,891.6953125,912.224426269531,,,13.6802587509155,-99999999,1,0,0,0,0.0139617919921875,30.3030319213867,1,6,1,139.998062133789,0,3154122112,139.999392422763,,,0.00243723775109547,0.000121619327297074,0.00243840893816454,0.000121621769619455,0.968345582485199,0.990954756736755,31.6856956481934,0.188887670636177,30,4,200,0.464562863111496,0.0203479509800673,1.95536327362061,1,,,,,,,,,,,,,,,,
,3740047327.73582,139.999710083008,1168.40606689453,,,6,,,,31.8006210327148,,,10,,,,,,,,,,,,,,,,,,,,,,139.999176025391,140.000946044922,1157.6474609375,1178.17651367188,,,13.7366809844971,-99999999,1,0,0,0,0.014801025390625,30.3030319213867,1,6,1,139.999267578125,0,3154122080,140.000166459517,,,0.003131963458527,0.000156289032198783,0.0031334781304293,0.00015629253194827,0.967828691005707,0.989355504512787,31.6855430603027,0.18887747824192,30,4,200,0.452704459428787,-0.310107588768005,1.86576700210571,1,,,,,,,,,,,,,,,,
,3740047460.39759,139.999336242676,1433.82751464844,,,6,,,,31.8006210327148,,,10,,,,,,,,,,,,,,,,,,,,,,139.998718261719,140.001327514648,1423.03845214844,1443.38464355469,,,13.7641820907593,-99999999,1,0,0,0,0.0139617919921875,30.3030319213867,1,6,1,139.998748779297,0,3154121888,140.000266335227,,,0.00382202844787191,0.000190716461414825,0.00382370915505364,0.000190720524082155,0.96910548210144,0.989126563072205,31.6910266876221,0.188876241445541,30,4,200,0.430559307336807,-0.654299557209015,1.78667175769806,1,,,,,,,,,,,,,,,,
,3740047593.86476,139.999069213867,1700.69451904297,,,6,,,,31.8006210327148,,,10,,,,,,,,,,,,,,,,,,,,,,139.99853515625,140.000930786133,1689.78344726562,1710.39794921875,,,13.7967519760132,-99999999,1,0,0,0,0.0139617919921875,30.3030319213867,1,6,1,139.998748779297,0,3154121824,139.999876542525,,,0.00445164992497728,0.000222110300935458,0.00445313356171562,0.00022211348754616,0.972794115543366,0.989867091178894,31.705041885376,0.188848897814751,30,4,200,0.413934916257858,-0.888336420059204,1.76398038864136,1,,,,,,,,,,,,,,,,
,3740047726.75255,139.999404907227,1966.42108154297,,,6,,,,31.8006210327148,,,10,,,,,,,,,,,,,,,,,,,,,,139.99919128418,140.000961303711,1955.50390625,1976.54528808594,,,13.8551340103149,-99999999,1,0,0,0,0.0139617919921875,30.3030319213867,1,6,1,139.999389648438,0,3154122112,139.999963933771,,,0.00508892079613753,0.000253918654907782,0.00509100571490072,0.000253923130018581,0.971061885356903,0.992666184902191,31.6945648193359,0.18886810541153,30,4,200,0.408714294433594,-1.08528029918671,1.808180809021,1,,,,,,,,,,,,,,,,
,3740047859.86222,139.998977661133,2232.65368652344,,,6,,,,31.8006210327148,,,10,,,,,,,,,,,,,,,,,,,,,,139.998199462891,140.000900268555,2221.74877929687,2242.75366210938,,,13.8945980072021,-99999999,1,0,0,0,0.0139617919921875,30.3030319213867,1,6,1,139.998428344727,0,3154122112,139.999809958718,,,0.00569528136059339,0.000284164652857548,0.00569748879208636,0.000284169350484454,0.972208499908447,0.994459331035614,31.6974391937256,0.188856810331345,30,4,200,0.406554967164993,-1.42315602302551,1.72892093658447,1,,,,,,,,,,,,,,,,
,3740047992.81757,139.99893951416,2493.97668457031,,,6,,,,31.8006210327148,,,10,,,,,,,,,,,,,,,,,,,,,,139.998809814453,140.001495361328,2487.810546875,2500.15502929687,,,13.9285135269165,-99999999,1,0,0,0,0.0139617919921875,30.3030319213867,1,6,1,139.999008178711,0,3154121792,139.999941739169,,,0.00627305507861054,0.000323404231381966,0.00630128302306558,0.000323466102188111,0.746867835521698,0.763367176055908,31.4484786987305,0.195157513022423,30,4,200,0.182524144649506,-2.49761819839478,1.82816350460052,1,,,,,,,,,,,,,,,,
,3740048138.2154,139.998908996582,2251.71301269531,,,6,,,,31.8006210327148,,,10,,,,,,,,,,,,,,,,,,,,,,139.998565673828,140.001022338867,2242.29028320313,2262.52661132813,,,13.9627552032471,-99999999,1,0,0,0,0.0139617919921875,30.3030319213867,1,6,1,139.998718261719,0,3154121856,139.999794699929,,,0.00572189336223337,0.000285498610487671,0.00572417676845963,0.000285503010979849,0.971434891223907,0.992989063262939,31.6957511901855,0.188869997859001,30,4,200,-0.483812123537064,-3.27471590042114,0.0106805376708508,1,,,,,,,,,,,,,,,,
,3740048271.30347,139.999031066895,1985.55963134766,,,6,,,,31.8006210327148,,,10,,,,,,,,,,,,,,,,,,,,,,139.998626708984,140.001251220703,1975.93542480469,1996.58666992187,,,14.0059757232666,-99999999,1,0,0,0,0.0139617919921875,30.3030319213867,1,6,1,139.998657226562,0,3154122048,140.000024968928,,,0.00512335885041698,0.000255641800696026,0.00512543392063116,0.000255645795567098,0.970406770706177,0.990125179290771,31.6949520111084,0.188874527812004,30,4,200,-0.471020370721817,-3.13432645797729,-0.0237784665077925,1,,,,,,,,,,,,,,,,
,3740048404.0167,139.999488830566,1720.11364746094,,,6,,,,31.8006210327148,,,10,,,,,,,,,,,,,,,,,,,,,,139.999267578125,140.001220703125,1710.31262207031,1730.90283203125,,,14.0296363830566,-99999999,1,0,0,0,0.014801025390625,30.3030319213867,1,6,1,139.999710083008,0,3154122080,140.000302401456,,,0.00449905843265666,0.000224492400559867,0.0045007522680994,0.000224495982817154,0.970199406147003,0.987056314945221,31.6989917755127,0.188869774341583,30,4,200,-0.453837424516678,-2.80990695953369,-0.0394140370190144,1,,,,,,,,,,,,,,,,
,3740048536.76343,139.999214172363,1454.78369140625,,,6,,,,31.8006210327148,,,10,,,,,,,,,,,,,,,,,,,,,,139.999237060547,140.000793457031,1444.88500976562,1465.51171875,,,14.0797920227051,-99999999,1,0,0,0,0.0139617919921875,30.3030319213867,1,6,1,139.999237060547,0,3154121920,139.999883478338,,,0.00384629306192711,0.000191930361752606,0.00384801001670775,0.000191933700022955,0.968596994876862,0.988649666309357,31.6897602081299,0.188882231712341,30,4,200,-0.439058542251587,-2.47453022003174,-0.0106063401326537,1,,,,,,,,,,,,,,,,
,3740048669.59557,139.999076843262,1189.01446533203,,,6,,,,31.8006210327148,,,10,,,,,,,,,,,,,,,,,,,,,,139.998504638672,140.000900268555,1178.84741210938,1199.82800292969,,,14.1191854476929,-99999999,1,0,0,0,0.0139617919921875,30.3030319213867,1,6,1,139.998489379883,0,3154122016,139.999889026989,,,0.00317804443270273,0.000158569405548228,0.00317913238848252,0.000158571433698381,0.971822440624237,0.988367736339569,31.7034797668457,0.188859716057777,30,4,200,-0.433001309633255,-2.26129841804504,-0.0879305899143219,1,,,,,,,,,,,,,,,,
,3740048803.29894,139.999237060547,921.653472900391,,,6,,,,31.8006210327148,,,10,,,,,,,,,,,,,,,,,,,,,,139.999176025391,140.000869750977,911.870788574219,932.473083496094,,,14.1475658416748,-99999999,1,0,0,0,0.0139617919921875,30.3030319213867,1,6,1,139.999298095703,0,3154122080,140.000041614879,,,0.00248733880097674,0.000124113880047882,0.00248825854556061,0.000124115675090125,0.969772577285767,0.985730648040771,31.6996364593506,0.188868880271912,30,4,200,-0.434427350759506,-1.98871600627899,-0.0513231232762337,1,,,,,,,,,,,,,,,,
,3740048936.24869,139.999061584473,656.274658203125,,,6,,,,31.8006210327148,,,10,,,,,,,,,,,,,,,,,,,,,,139.998931884766,140.000869750977,646.528503417969,667.045471191406,,,14.1903133392334,-99999999,1,0,0,0,0.0139617919921875,30.3030319213867,1,6,1,139.999053955078,0,3154121984,139.999891801314,,,0.00178215607492332,8.89471278517595E-5,0.00178292719877242,8.89486362654305E-5,0.962884485721588,0.97661018371582,31.6915035247803,0.188905879855156,30,4,200,-0.429444849491119,-1.83518242835999,-0.0881007090210915,1,,,,,,,,,,,,,,,,
,3740049068.94159,139.999282836914,390.80436706543,,,6,,,,31.8006210327148,,,10,,,,,,,,,,,,,,,,,,,,,,139.999084472656,140.00080871582,380.783721923828,401.617858886719,,,14.2313537597656,-99999999,1,0,0,0,0.0139617919921875,30.3030319213867,1,6,1,139.999481201172,0,3154122048,139.999956997958,,,0.00105884774369073,5.28506549693419E-5,0.00105916457310567,5.2851356784229E-5,0.961037933826447,0.969227373600006,31.7100639343262,0.188939079642296,30,4,200,-0.427628815174103,-1.78557074069977,-0.0453668683767319,1,,,,,,,,,,,,,,,,
,3740049202.18672,139.999198913574,124.382606506348,,,6,,,,31.8006210327148,,,10,,,,,,,,,,,,,,,,,,,,,,139.999008178711,140.001022338867,114.490058898926,135.080215454102,,,14.2756881713867,-99999999,1,0,0,0,0.014801025390625,30.3030319213867,1,6,1,139.999053955078,0,3154122112,139.999990289862,,,0.000310663791191882,1.55598709930616E-5,0.000310705442693638,1.55599377389962E-5,0.90843278169632,0.909849286079407,31.7397403717041,0.189584374427795,30,4,200,-0.416505694389343,-1.7337042093277,-0.0256296526640654,1,,,,,,,,,,,,,,,,
,3740049290.41025,139.99983215332,-0.0731877610087395,,,6,,,,31.8006210327148,,,1,,,,,,,,,,,,,,,,,,,,,,139.999725341797,140.001525878906,-0.097583681344986,0,,,14.3201932907104,-99999999,1,0,0,0,0.0139617919921875,30.3030319213867,1,4,1,139.999938964844,0,3154121824,140.000668612393,,,-2.06478776197638E-5,1.67104202179999E-6,-2.20963191869701E-5,1.67522036754051E-6,0.212469547986984,0.246861800551414,33.0333786010742,0.306521207094193,30,4,200,0.0373047515749931,-0.723787367343903,0.483218610286713,1,,,,,,,,,,,,,,,,