File: Observation of a Zero-Field Josephson Diode Effect in a Helimagnet Josephson Junction/Figure 1/Magnetic Characterization/CNS_KL180615_003_abplane_002.dat
[Header]
; MPMS3 Data File (default extension .dat)
; Copyright (c) 2007, Quantum Design, Inc. All rights reserved.
TITLE,
FILEOPENTIME,3739963366.13896,07/05/2018,2:44 pm
BYAPP,SQUID AC,0.9.1.0
INFO,MPMS3 Measurement Release 1.1.16 Build 347, MultiVu Release 2.3.3.2,APPNAME
INFO,1,MOMENT_UNITS
INFO,CrNb3S6,SAMPLE_MATERIAL
INFO,003 abplane,SAMPLE_COMMENT
INFO,,SAMPLE_MASS
INFO,,SAMPLE_VOLUME
INFO,,SAMPLE_MOLECULAR_WEIGHT
INFO,,SAMPLE_SIZE
INFO,disk,SAMPLE_SHAPE
INFO,Quartz,SAMPLE_HOLDER
INFO,Standard,SAMPLE_HOLDER_DETAIL
INFO,67.1,SAMPLE_OFFSET
DATATYPE,COMMENT,1
DATATYPE,TIME,2
STARTUPAXIS,X,2
STARTUPAXIS,Y1,5
FIELDGROUP, VSM,2,3,4,5,6,8,9,10,11,14,15
FIELDGROUP, DC, 2,3,4,14,56,57,58,59,60,61,62,63,64,65,66,67,68,69
FIELDGROUP, AC, 2,3,4,11,16,17,18,19,20,21,22,23,24,25,26,27,28,29,30
STARTUPGROUP, All
[Data]
Comment,Time Stamp (sec),Temperature (K),Magnetic Field (Oe),Moment (Am2),M. Std. Err. (Am2),Transport Action,Averaging Time (sec),Frequency (Hz),Peak Amplitude (mm),Center Position (mm),Lockin Signal' (V),Lockin Signal (V),Range,M. Quad. Signal (Am2),AC Moment (Am2),AC M. Std Err. (Am2),AC Phase (deg),AC Phase Std. Err. (deg),AC Susceptibility (Am2/T),AC Suscept. Std Err. (Am2/T),AC X' (Am2/T),AC X' Std Err. (Am2/T),AC X'' (Am2/T),AC X'' Std Err. (Am2/T),AC Drive (T),AC Frequency (Hz),AC Averaging Time (sec),AC Cycles,AC Range,AC Measure Type,AC Signal' (V),AC Signal'' (V),AC Trim Coil Ratio,AC Trim Coil Phase,Min. Temperature (K),Max. Temperature (K),Min. Field (Oe),Max. Field (Oe),Mass (grams),Motor Lag (deg),Pressure (Torr),Measure Count,Measurement Number,SQUID Status (code),Motor Status (code),Measure Status (code),Motor Current (amps),Motor Temp. (C),Temp. Status (code),Field Status (code),Chamber Status (code),Chamber Temp (K),Redirection State,Evercool Status,Average Temp (K),Rotation Angle (deg),Rotator state,DC Moment Fixed Ctr (emu),DC Moment Err Fixed Ctr (emu),DC Moment Free Ctr (emu),DC Moment Err Free Ctr (emu),DC Fixed Fit,DC Free Fit,DC Calculated Center (mm),DC Calculated Center Err (mm),DC Scan Length (mm),DC Scan Time (s),DC Number of Points,DC Squid Drift,DC Min V (V),DC Max V (V),DC Scans per Measure,Map 01,Map 02,Map 03,Map 04,Map 05,Map 06,Map 07,Map 08,Map 09,Map 10,Map 11,Map 12,Map 13,Map 14,Map 15,Map 16
,3739966236.15452,2.00074112415314,499.652862548828,,,6,,,,31.5662807256906,,,10,,,,,,,,,,,,,,,,,,,,,,1.99879050254822,2.00106859207153,499.652862548828,499.652862548828,,,3.40823340415955,-99999999,1,0,0,0,0,30.3030319213867,1,1,1,2.00041365623474,0,3154122080,2.00002635660626,,,0.0106053443184943,0.000529033884295685,0.0106069452422121,0.00052903596780767,0.981843769550323,0.994025647640228,31.631290435791,0.188835471868515,30,4,200,0.00294186337850988,-4.58907175064087,4.89376831054687,1,,,,,,,,,,,,,,,,
,3739966304.39806,6.52987194061279,499.652862548828,,,6,,,,31.5662807256906,,,10,,,,,,,,,,,,,,,,,,,,,,6.04009819030762,6.98231077194214,499.652862548828,499.652862548828,,,6.4449315071106,-99999999,1,0,0,0,0,30.3030319213867,6,1,1,7.01964569091797,0,3154122176,6.51484515450217,,,0.010564669846059,0.000527004692360388,0.0105663060433712,0.000527006698647429,0.98184734582901,0.994759619235992,31.6321582794189,0.188818380236626,30,4,200,0.00290724472142756,-4.1187686920166,0.591464400291443,1,,,,,,,,,,,,,,,,
,3739966369.13392,12.5396032333374,499.652862548828,,,6,,,,31.5662807256906,,,10,,,,,,,,,,,,,,,,,,,,,,12.0291156768799,12.9935846328735,499.652862548828,499.652862548828,,,7.73195123672485,-99999999,1,0,0,0,0.00030517578125,30.3030319213867,6,1,1,13.0500907897949,0,3154122016,12.5115751786666,,,0.0105139082726446,0.000524475388920604,0.0105156153475043,0.000524478383635409,0.981548666954041,0.994781851768494,31.6333694458008,0.18884913623333,30,4,200,0.00339649198576808,-4.10068511962891,0.587379276752472,1,,,,,,,,,,,,,,,,
,3739966431.30669,18.5410718917847,499.652862548828,,,6,,,,31.5662807256906,,,10,,,,,,,,,,,,,,,,,,,,,,18.0179195404053,18.9736232757568,499.652862548828,499.652862548828,,,8.35684013366699,-99999999,1,0,0,0,0,30.3030319213867,2,1,1,19.0642242431641,0,3154122176,18.5168800354004,,,0.0104538356786569,0.000521480979868509,0.0104555846978275,0.000521483720636889,0.981312692165375,0.994980275630951,31.6345119476318,0.188848659396172,30,4,200,0.00293806963600218,-4.08184766769409,0.579554796218872,1,,,,,,,,,,,,,,,,
,3739966494.5959,24.5571546554565,499.652862548828,,,6,,,,31.5662807256906,,,10,,,,,,,,,,,,,,,,,,,,,,24.0218601226807,25.0516796112061,499.652862548828,499.652862548828,,,8.7418155670166,-99999999,1,0,0,0,0.0151824951171875,30.3030319213867,2,1,1,25.0924491882324,0,3154122144,24.5462110692804,,,0.0103820408195058,0.000517903052187932,0.0103838480864425,0.000517905729478386,0.980964243412018,0.995035886764526,31.6359329223633,0.188831448554993,30,4,200,0.00266297953203321,-4.05946683883667,0.569937407970428,1,,,,,,,,,,,,,,,,
,3739966567.55684,31.5066404342651,499.652862548828,,,6,,,,31.5712807938817,,,10,,,,,,,,,,,,,,,,,,,,,,30.4665546417236,32.4712028503418,499.652862548828,499.652862548828,,,9.05783271789551,-99999999,1,0,0,0,0.0139617919921875,30.3030319213867,2,1,1,32.5467262268066,0,3154121824,31.4864095960345,,,0.0102737447860845,0.000512494499769021,0.0102753919928974,0.000512496265562146,0.981602847576141,0.995023429393768,31.6384086608887,0.188825666904449,30,4,200,0.00259626493789256,-4.53459501266479,4.85045146942139,1,,,,,,,,,,,,,,,,
,3739966620.20954,36.5482292175293,499.652862548828,,,6,,,,31.5712807938817,,,10,,,,,,,,,,,,,,,,,,,,,,36.018684387207,37.0324821472168,499.652862548828,499.652862548828,,,9.19894123077393,-99999999,1,0,0,0,0,30.3030319213867,2,1,1,37.0777740478516,0,3154122208,36.5309600830078,,,0.0101976000137056,0.000508698514706136,0.0101992971116649,0.000508701219609004,0.981357455253601,0.994957804679871,31.6393089294434,0.188833564519882,30,4,200,0.00273332861252129,-4.00028324127197,0.548004686832428,1,,,,,,,,,,,,,,,,
,3739966683.1282,42.56689453125,499.652862548828,,,6,,,,31.5712807938817,,,10,,,,,,,,,,,,,,,,,,,,,,42.0083351135254,43.0617942810059,499.652862548828,499.652862548828,,,9.34504985809326,-99999999,1,0,0,0,0,30.3030319213867,2,1,1,43.146427154541,0,3154122080,42.5542366721413,,,0.0100836294704674,0.000503019104704714,0.0100854082607461,0.000503020802933014,0.980735957622528,0.994985342025757,31.6417980194092,0.18888358771801,30,4,200,0.00258180079981685,-3.96246075630188,0.535574555397034,1,,,,,,,,,,,,,,,,
,3739966744.85576,48.5169715881348,499.652862548828,,,6,,,,31.5712807938817,,,10,,,,,,,,,,,,,,,,,,,,,,48.0267219543457,48.9788932800293,499.652862548828,499.652862548828,,,9.50891494750977,-99999999,1,0,0,0,0.01495361328125,30.3030319213867,2,1,1,49.0072212219238,0,3154122144,48.4904972423207,,,0.00996138878725419,0.000496929193539102,0.00996332283476377,0.000496931538110169,0.979902803897858,0.99498575925827,31.645055770874,0.188868805766106,30,4,200,0.00253001227974892,-3.92263174057007,0.522106885910034,1,,,,,,,,,,,,,,,,
,3739966807.13463,54.5404472351074,499.652862548828,,,6,,,,31.5762845612122,,,10,,,,,,,,,,,,,,,,,,,,,,54.0009994506836,55.0333824157715,499.652862548828,499.652862548828,,,9.78741073608398,-99999999,1,0,0,0,0,30.3030319213867,2,1,1,55.0798950195313,0,3154122144,54.5404586791992,,,0.00983742197965107,0.000490742892950372,0.00983930377231101,0.000490745958980198,0.980123817920685,0.994990706443787,31.6491966247559,0.188862890005112,30,4,200,0.00238461093977094,-3.88243699073791,0.506848573684692,1,,,,,,,,,,,,,,,,
,3739966869.91849,60.6053428649902,499.652862548828,,,6,,,,31.5762845612122,,,10,,,,,,,,,,,,,,,,,,,,,,60.0824165344238,61.0802955627441,499.652862548828,499.652862548828,,,9.94130039215088,-99999999,1,0,0,0,0,30.3030319213867,2,1,1,61.1282691955566,0,3154122144,60.5743727250533,,,0.00969513439527096,0.000483653081285645,0.00969714810326335,0.000483656104439971,0.979295790195465,0.994911313056946,31.652364730835,0.188870877027512,30,4,200,0.00226791831664741,-3.83742666244507,0.489632666110992,1,,,,,,,,,,,,,,,,
,3739966934.7369,66.9327430725098,499.652862548828,,,6,,,,31.5812871974361,,,10,,,,,,,,,,,,,,,,,,,,,,66.4153594970703,67.4049301147461,499.652862548828,499.652862548828,,,10.1940755844116,-99999999,1,0,0,0,0,30.3030319213867,2,1,1,67.4501266479492,0,3154122144,66.9191797429865,,,0.00951334928341755,0.000474581255158048,0.00951525388480214,0.000474583413946502,0.979622185230255,0.995093643665314,31.6562538146973,0.188855320215225,30,4,200,0.00214864988811314,-3.77407217025757,0.576466083526611,1,,,,,,,,,,,,,,,,
,3739966992.25782,72.5336151123047,499.652862548828,,,6,,,,31.5812871974361,,,10,,,,,,,,,,,,,,,,,,,,,,72.0015258789063,73.0164489746094,499.652862548828,499.652862548828,,,10.614767074585,-99999999,1,0,0,0,0,30.3030319213867,2,1,1,73.0657043457031,0,3154121984,72.5215350064364,,,0.0093522655308815,0.000466550750873309,0.00935423905170363,0.000466552467524985,0.979068636894226,0.995143949985504,31.6584568023682,0.188855588436127,30,4,200,0.00211150711402297,-3.61822819709778,0.556689083576202,1,,,,,,,,,,,,,,,,
,3739967057.63781,78.874340057373,499.652862548828,,,6,,,,31.5862915158311,,,10,,,,,,,,,,,,,,,,,,,,,,78.3305969238281,79.368049621582,499.652862548828,499.652862548828,,,11.4723863601685,-99999999,1,0,0,0,0,30.3030319213867,2,1,1,79.418083190918,0,3154121952,78.8556227250533,,,0.00917184629195283,0.000457548589714325,0.00917377270447721,0.000457551489292903,0.979242920875549,0.99514240026474,31.6627712249756,0.188835099339485,30,4,200,0.00209095189347863,-3.56043982505798,0.534623861312866,1,,,,,,,,,,,,,,,,
,3739967116.19786,84.589958190918,499.652862548828,,,6,,,,31.5862915158311,,,10,,,,,,,,,,,,,,,,,,,,,,84.0319519042969,85.1059875488281,499.652862548828,499.652862548828,,,11.69602394104,-99999999,1,0,0,0,0.0160980224609375,30.3030319213867,2,1,1,85.1479644775391,0,3154121952,84.5815395008434,,,0.0089830259295576,0.000448136654359337,0.00898505342816706,0.000448139036096531,0.978447318077087,0.995111286640167,31.6658535003662,0.188863694667816,30,4,200,0.00198014383204281,-3.49968934059143,0.511714041233063,1,,,,,,,,,,,,,,,,
,3739967245.0819,89.9670829772949,499.652862548828,,,6,,,,31.5912956426755,,,10,,,,,,,,,,,,,,,,,,,,,,89.959358215332,89.9737548828125,499.652862548828,499.652862548828,,,11.7585020065308,-99999999,1,0,0,0,0,30.3030319213867,1,1,1,89.9748077392578,0,3154122304,89.9669016057795,,,0.00871802566630077,0.000434920121155124,0.0087200730892611,0.000434922734949227,0.978080928325653,0.995210707187653,31.6723709106445,0.188869744539261,30,4,200,0.0022029965184629,-3.41124582290649,0.477935075759888,1,,,,,,,,,,,,,,,,
,3739967286.65145,90.1248626708984,499.652862548828,,,6,,,,31.5912956426755,,,10,,,,,,,,,,,,,,,,,,,,,,90.0690078735352,90.1614074707031,499.652862548828,499.652862548828,,,11.787296295166,-99999999,1,0,0,0,0.0276947021484375,30.3030319213867,2,1,1,90.1807174682617,0,3154122240,90.1174896240234,,,0.00870446002574487,0.000420979094082884,0.00870478879450814,0.000420902646857815,0.966735363006592,0.974151134490967,31.6721820831299,0.186555400490761,60,1.1,200,-0.000356743868906051,-2.97307157516479,1.01930212974548,1,,,,,,,,,,,,,,,,
,3739967338.09304,91.6209869384766,499.652862548828,,,6,,,,31.5912956426755,,,10,,,,,,,,,,,,,,,,,,,,,,91.5236434936523,91.6936645507812,499.652862548828,499.652862548828,,,11.8080492019653,-99999999,1,0,0,0,0.0246429443359375,30.3030319213867,2,1,1,91.7183303833008,0,3154122080,91.6078262329102,,,0.00865772514823767,0.000418717945615876,0.0086580161585205,0.000418641138309704,0.966785728931427,0.974126398563385,31.6717491149902,0.186532214283943,60,1.1,200,0.000976297771558166,-2.95625853538513,1.01310312747955,1,,,,,,,,,,,,,,,,
,3739967382.91724,93.1230316162109,499.652862548828,,,6,,,,31.5912956426755,,,10,,,,,,,,,,,,,,,,,,,,,,93.0243453979492,93.1990432739258,499.652862548828,499.652862548828,,,11.8275356292725,-99999999,1,0,0,0,0.0384521484375,30.3030319213867,2,1,1,93.2290191650391,0,3154122144,93.1079498291016,,,0.00860204179301811,0.000416023183300023,0.00860232019349989,0.000415948265479951,0.966914594173431,0.974113762378693,31.6708927154541,0.186535730957985,60,1.1,200,0.00254279491491616,-2.82641053199768,1.00740551948547,1,,,,,,,,,,,,,,,,
,3739967427.90421,94.6194610595703,499.652862548828,,,6,,,,31.5963081229661,,,10,,,,,,,,,,,,,,,,,,,,,,94.5235824584961,94.7153396606445,499.652862548828,499.652862548828,,,11.8562002182007,-99999999,1,0,0,0,0.028076171875,30.3030319213867,2,1,1,94.7153396606445,0,3154121984,94.6169242858887,,,0.00854298349904345,0.000413158007756391,0.00854314712452329,0.000413088122413076,0.967576146125793,0.974019289016724,31.6712532043457,0.186549007892609,60,1.1,200,0.00111874588765204,-2.80558228492737,1.00107491016388,1,,,,,,,,,,,,,,,,
,3739967473.60791,96.1193199157715,499.652862548828,,,6,,,,31.5963081229661,,,10,,,,,,,,,,,,,,,,,,,,,,96.0193405151367,96.1884994506836,499.652862548828,499.652862548828,,,11.8875570297241,-99999999,1,0,0,0,0.0212860107421875,30.3030319213867,2,1,1,96.2192993164062,0,3154122048,96.1053115844727,,,0.00848463624317229,0.000410334580090611,0.00848477183265343,0.00041026403558137,0.967684745788574,0.974139451980591,31.6711826324463,0.186568930745125,60,1.1,200,0.00324996537528932,-2.78635430335999,0.993020474910736,1,,,,,,,,,,,,,,,,
,3739967518.80806,97.6283187866211,499.652862548828,,,6,,,,31.5963081229661,,,10,,,,,,,,,,,,,,,,,,,,,,97.5251312255859,97.7028198242188,499.652862548828,499.652862548828,,,11.9130544662476,-99999999,1,0,0,0,0.0206756591796875,30.3030319213867,2,1,1,97.7315063476563,0,3154121984,97.6085388183594,,,0.00842558138952254,0.00040748395507532,0.00842578626676173,0.000407412285330378,0.967281639575958,0.974107682704926,31.6735820770264,0.186549305915833,60,1.1,200,0.000725964899174869,-2.76786804199219,0.984551131725311,1,,,,,,,,,,,,,,,,
,3739967563.72978,99.1230239868164,499.652862548828,,,6,,,,31.5963081229661,,,10,,,,,,,,,,,,,,,,,,,,,,99.0222396850586,99.1953430175781,499.652862548828,499.652862548828,,,11.9298315048218,-99999999,1,0,0,0,0.037689208984375,30.3030319213867,2,1,1,99.2238082885742,0,3154122144,99.1076629638672,,,0.0083570025971967,0.000404173628715324,0.00835730218694023,0.000404098394372645,0.966812133789063,0.974352240562439,31.6776847839355,0.186565533280373,60,1.1,200,0.00120224116835743,-2.74943709373474,0.977479755878449,1,,,,,,,,,,,,,,,,
,3739967611.54425,100.705795288086,499.652862548828,,,6,,,,31.6013148807898,,,10,,,,,,,,,,,,,,,,,,,,,,100.607269287109,100.778900146484,499.652862548828,499.652862548828,,,11.9514989852905,-99999999,1,0,0,0,0.0328826904296875,30.3030319213867,2,1,1,100.804321289062,0,3154122112,100.694981384277,,,0.00827806761898483,0.000400298442045282,0.00827895498257726,0.000400254733970902,0.971463084220886,0.980459094047546,31.6816329956055,0.186493158340454,60,1.1,200,0.000748636375647038,-2.72679686546326,0.969144642353058,1,,,,,,,,,,,,,,,,
,3739967654.42544,102.123542785645,499.652862548828,,,6,,,,31.6013148807898,,,10,,,,,,,,,,,,,,,,,,,,,,102.025299072266,102.194793701172,499.652862548828,499.652862548828,,,11.9665002822876,-99999999,1,0,0,0,0.0292205810546875,30.3030319213867,2,1,1,102.221786499023,0,3154122176,102.110531616211,,,0.00823926005152865,0.000398469654124762,0.00823942029723828,0.000398400571166138,0.967552185058594,0.97416353225708,31.677152633667,0.18655201792717,60,1.1,200,0.00255143758840859,-2.71133470535278,0.960953831672668,1,,,,,,,,,,,,,,,,
,3739967699.50079,103.621513366699,499.652862548828,,,6,,,,31.6013148807898,,,10,,,,,,,,,,,,,,,,,,,,,,103.517509460449,103.694633483887,499.652862548828,499.652862548828,,,11.9970207214355,-99999999,1,0,0,0,0.029449462890625,30.3030319213867,2,1,1,103.725517272949,0,3154122112,103.608474731445,,,0.00817390915509557,0.000395310873124181,0.00817410454999886,0.000395241898977487,0.967401385307312,0.974188923835754,31.6782512664795,0.186563834547997,60,1.1,200,0.00306608551181853,-2.68837952613831,0.953944444656372,1,,,,,,,,,,,,,,,,
,3739967744.66626,105.127910614014,499.652862548828,,,6,,,,31.6013148807898,,,10,,,,,,,,,,,,,,,,,,,,,,105.019798278809,105.19930267334,499.652862548828,499.652862548828,,,12.022575378418,-99999999,1,0,0,0,0.023040771484375,30.3030319213867,2,1,1,105.236022949219,0,3154122176,105.106033325195,,,0.00811107703683624,0.000392273773452976,0.00811126442061122,0.000392201179283772,0.967266499996185,0.974397599697113,31.6801166534424,0.186557322740555,60,1.1,200,0.00194004585500807,-2.6680474281311,0.947131752967834,1,,,,,,,,,,,,,,,,
,3739967789.59369,106.633514404297,499.652862548828,,,6,,,,31.6013148807898,,,10,,,,,,,,,,,,,,,,,,,,,,106.535278320312,106.704818725586,499.652862548828,499.652862548828,,,12.0564584732056,-99999999,1,0,0,0,0.0250244140625,30.3030319213867,2,1,1,106.731750488281,0,3154121984,106.616636657715,,,0.00804827688563452,0.000389238134463271,0.00804851328043881,0.000389166565996096,0.967150747776031,0.97444748878479,31.6810665130615,0.186546117067337,60,1.1,200,0.00231626746244729,-2.65185451507568,0.937569379806519,1,,,,,,,,,,,,,,,,
,3739967834.86668,108.128803253174,499.652862548828,,,6,,,,31.6063152137584,,,10,,,,,,,,,,,,,,,,,,,,,,108.02498626709,108.211181640625,499.652862548828,499.652862548828,,,12.0927400588989,-99999999,1,0,0,0,0.0304412841796875,30.3030319213867,2,1,1,108.232620239258,0,3154122240,108.120374043783,,,0.00797811413904433,0.0003858400928544,0.00797827889059759,0.000385773053638584,0.967533349990845,0.974200963973999,31.682466506958,0.186550602316856,60,1.1,200,0.00203053676523268,-2.62631154060364,0.929634749889374,1,,,,,,,,,,,,,,,,
,3739967879.83146,109.628211975098,499.652862548828,,,6,,,,31.6063152137584,,,10,,,,,,,,,,,,,,,,,,,,,,109.524604797363,109.707641601562,499.652862548828,499.652862548828,,,12.1189155578613,-99999999,1,0,0,0,0.023345947265625,30.3030319213867,2,1,1,109.731819152832,0,3154122240,109.617698669434,,,0.00791513941207552,0.000382796084118744,0.00791536033668211,0.000382729203505558,0.967391014099121,0.974340498447418,31.6840591430664,0.186556816101074,60,1.1,200,0.00135736481752247,-2.60534024238586,0.925851821899414,1,,,,,,,,,,,,,,,,
,3739967925.20229,111.117538452148,499.652862548828,,,6,,,,31.6063152137584,,,10,,,,,,,,,,,,,,,,,,,,,,111.021743774414,111.213333129883,499.652862548828,499.652862548828,,,12.1501522064209,-99999999,1,0,0,0,0.0214385986328125,30.3030319213867,2,1,1,111.213333129883,0,3154121984,111.117655436198,,,0.00784846159578956,0.000379577249649485,0.00784872713162976,0.00037950698446202,0.966934561729431,0.974391877651215,31.6871318817139,0.186552181839943,60,1.1,200,0.00109269458334893,-2.58468651771545,0.916442930698395,1,,,,,,,,,,,,,,,,
,3739967970.25657,112.637844085693,499.652862548828,,,6,,,,31.6063152137584,,,10,,,,,,,,,,,,,,,,,,,,,,112.522621154785,112.714790344238,499.652862548828,499.652862548828,,,12.184268951416,-99999999,1,0,0,0,0.0222015380859375,30.3030319213867,2,1,1,112.753067016602,0,3154122048,112.625311279297,,,0.007775071354089,0.000376031824624615,0.00777542581011656,0.000375961235769676,0.966622292995453,0.974547505378723,31.689733505249,0.186553761363029,60,1.1,200,-8.35831669974141E-5,-2.56163740158081,0.908008456230164,1,,,,,,,,,,,,,,,,
,3739968015.56534,114.124011993408,499.652862548828,,,6,,,,31.6113193710267,,,10,,,,,,,,,,,,,,,,,,,,,,114.021766662598,114.200355529785,499.652862548828,499.652862548828,,,12.2163400650024,-99999999,1,0,0,0,0.029144287109375,30.3030319213867,2,1,1,114.226257324219,0,3154122112,114.111614990234,,,0.00771383791067682,0.000373058772938106,0.00771403077955936,0.000372991806188078,0.967564404010773,0.974635362625122,31.6894245147705,0.186545327305794,60,1.1,200,0.000349068199284375,-2.54162192344666,0.899425387382507,1,,,,,,,,,,,,,,,,
,3739968060.99503,115.617721557617,499.652862548828,,,6,,,,31.6113193710267,,,10,,,,,,,,,,,,,,,,,,,,,,115.52384185791,115.711601257324,499.652862548828,499.652862548828,,,12.2530822753906,-99999999,1,0,0,0,0.023193359375,30.3030319213867,2,1,1,115.711601257324,0,3154122144,115.62455368042,,,0.0076535890713117,0.000370146725364778,0.00765378048523513,0.000370079076776104,0.967425465583801,0.974585771560669,31.6900482177734,0.186552822589874,60,1.1,200,-0.000629598274827004,-2.52330565452576,0.892050504684448,1,,,,,,,,,,,,,,,,
,3739968105.67715,117.124248504639,499.652862548828,,,6,,,,31.6113193710267,,,10,,,,,,,,,,,,,,,,,,,,,,117.027214050293,117.190147399902,499.652862548828,499.652862548828,,,12.3018751144409,-99999999,1,0,0,0,0.021820068359375,30.3030319213867,2,1,1,117.221282958984,0,3154122080,117.109115600586,,,0.00758874416280957,0.000367016680139572,0.0075890222464708,0.000366949902770145,0.966922879219055,0.974362790584564,31.6920680999756,0.186552807688713,60,1.1,200,-0.0014858387876302,-2.50160121917725,0.884879410266876,1,,,,,,,,,,,,,,,,
,3739968150.76412,118.624244689941,499.652862548828,,,6,,,,31.6113193710267,,,10,,,,,,,,,,,,,,,,,,,,,,118.520622253418,118.70142364502,499.652862548828,499.652862548828,,,12.3450508117676,-99999999,1,0,0,0,0.0281524658203125,30.3030319213867,2,1,1,118.727867126465,0,3154122080,118.612879943848,,,0.00753171785251653,0.00036425651340965,0.00753196961753603,0.000364188503789857,0.967114388942718,0.974671423435211,31.6923580169678,0.186551287770271,60,1.1,200,0.00139270548243076,-2.4819073677063,0.877050340175629,1,,,,,,,,,,,,,,,,
,3739968196.95656,120.139526367188,499.652862548828,,,6,,,,31.6163282177889,,,10,,,,,,,,,,,,,,,,,,,,,,120.039749145508,120.206512451172,499.652862548828,499.652862548828,,,12.3794441223145,-99999999,1,0,0,0,0.029449462890625,30.3030319213867,2,1,1,120.239303588867,0,3154122112,120.120518493652,,,0.00746359715775077,0.000360917228836576,0.00746455085604944,0.000360878232497961,0.971113324165344,0.980945587158203,31.7001705169678,0.186488538980484,60,1.1,200,-0.000604667293373495,-2.46376514434814,0.870262324810028,1,,,,,,,,,,,,,,,,
,3739968241.43647,121.627052307129,499.652862548828,,,6,,,,31.6163282177889,,,10,,,,,,,,,,,,,,,,,,,,,,121.524719238281,121.703895568848,499.652862548828,499.652862548828,,,12.4113330841064,-99999999,1,0,0,0,0.0283050537109375,30.3030319213867,2,1,1,121.729385375977,0,3154122176,121.617176055908,,,0.00743438424906677,0.000359544949198772,0.00743458943691473,0.000359479665955639,0.967465817928314,0.974692821502686,31.6953086853027,0.18653704226017,60,1.1,200,0.00121392426081002,-2.44886159896851,0.86704009771347,1,,,,,,,,,,,,,,,,
,3739968286.4854,123.128360748291,499.652862548828,,,6,,,,31.6163282177889,,,10,,,,,,,,,,,,,,,,,,,,,,123.024070739746,123.201728820801,499.652862548828,499.652862548828,,,12.4490566253662,-99999999,1,0,0,0,0.0276947021484375,30.3030319213867,2,1,1,123.232650756836,0,3154122144,123.108392333984,,,0.00739983770323345,0.000357874962080641,0.00740004766135113,0.000357809448219234,0.967391908168793,0.974687159061432,31.6957607269287,0.186572924256325,60,1.1,200,0.000963195168878883,-2.43991732597351,0.860804796218872,1,,,,,,,,,,,,,,,,
,3739968331.46516,124.62211227417,499.652862548828,,,6,,,,31.6163282177889,,,10,,,,,,,,,,,,,,,,,,,,,,124.515548706055,124.688835144043,499.652862548828,499.652862548828,,,12.4815187454224,-99999999,1,0,0,0,0.0213623046875,30.3030319213867,2,1,1,124.728675842285,0,3154122048,124.60472869873,,,0.00738956822227486,0.000357381457047284,0.00738981542263935,0.000357314686007689,0.96713000535965,0.974697649478912,31.6973934173584,0.186553210020065,60,1.1,200,0.00040947861270979,-2.43601179122925,0.859482228755951,1,,,,,,,,,,,,,,,,
,3739968377.44561,126.135314941406,499.652862548828,,,6,,,,31.6213304198827,,,10,,,,,,,,,,,,,,,,,,,,,,126.032539367676,126.204811096191,499.652862548828,499.652862548828,,,12.5132627487183,-99999999,1,0,0,0,0.0301361083984375,30.3030319213867,2,1,1,126.238090515137,0,3154122048,126.119514465332,,,0.0074142772601136,0.000358529999856937,0.00741529586732614,0.000358493728740498,0.971336126327515,0.981431126594543,31.7056636810303,0.186496943235397,60,1.1,200,0.00092646008124575,-2.44746875762939,0.861573457717896,1,,,,,,,,,,,,,,,,
,3739968421.99852,127.633724212646,499.652862548828,,,6,,,,31.6213304198827,,,10,,,,,,,,,,,,,,,,,,,,,,127.525451660156,127.714950561523,499.652862548828,499.652862548828,,,12.531397819519,-99999999,1,0,0,0,0.0240325927734375,30.3030319213867,2,1,1,127.741996765137,0,3154122144,127.617199707031,,,0.00754328138784424,0.000364812044482246,0.00754351229941756,0.000364745663431433,0.967410624027252,0.974756062030792,31.7009658813477,0.186567738652229,60,1.1,200,-0.000724103127140552,-2.48701190948486,0.878298759460449,1,,,,,,,,,,,,,,,,
,3739968466.9935,129.124237060547,499.652862548828,,,6,,,,31.6213304198827,,,10,,,,,,,,,,,,,,,,,,,,,,129.021209716797,129.201599121094,499.652862548828,499.652862548828,,,12.5469961166382,-99999999,1,0,0,0,0.02655029296875,30.3030319213867,2,1,1,129.227264404297,0,3154122112,129.116818237305,,,0.00817777526063565,0.000395531835246809,0.00817832191639348,0.00039544814539618,0.964865803718567,0.973960936069489,31.7124710083008,0.186568602919579,60,1.1,200,-0.00208580493927002,-2.7097475528717,0.963382303714752,1,,,,,,,,,,,,,,,,
,3739968511.57867,130.61669921875,499.652862548828,,,6,,,,31.6213304198827,,,10,,,,,,,,,,,,,,,,,,,,,,130.521423339844,130.681045532227,499.652862548828,499.652862548828,,,12.5601511001587,-99999999,1,0,0,0,0.02471923828125,30.3030319213867,2,1,1,130.711975097656,0,3154122176,130.600787353516,,,0.00972068278725545,0.000470169878171943,0.00972145552527177,0.000470067856761478,0.964114427566528,0.973630368709564,31.7154026031494,0.186575368046761,60,1.1,200,-0.000920429010875523,-3.26560139656067,1.15461111068726,1,,,,,,,,,,,,,,,,
,3739968557.87614,132.135116577148,499.652862548828,,,6,,,,31.6263326634739,,,10,,,,,,,,,,,,,,,,,,,,,,132.037536621094,132.20556640625,499.652862548828,499.652862548828,,,12.5712985992432,-99999999,1,0,0,0,0.030517578125,30.3030319213867,2,1,1,132.232696533203,0,3154122080,132.122601318359,,,0.0103780064657289,0.000501795874463377,0.0103780614108905,0.000501772506135637,0.975063741207123,0.977237224578857,31.665641784668,0.186479225754738,60,1.1,200,0.00110635336022824,-3.56297993659973,1.20437657833099,1,,,,,,,,,,,,,,,,
,3739968602.60548,133.625,499.652862548828,,,6,,,,31.6263326634739,,,10,,,,,,,,,,,,,,,,,,,,,,133.515899658203,133.705993652344,499.652862548828,499.652862548828,,,12.5821056365967,-99999999,1,0,0,0,0.02471923828125,30.3030319213867,2,1,1,133.734100341797,0,3154122208,133.615032958984,,,0.00729672741428447,0.000352948587614477,0.00729644673735465,0.000352922500124768,0.962523102760315,0.963479876518249,31.6588478088379,0.186621353030205,60,1.1,200,0.0051941554993391,-2.4694128036499,0.873599231243134,1,,,,,,,,,,,,,,,,
,3739968647.6296,135.120140075684,499.652862548828,,,6,,,,31.6263326634739,,,10,,,,,,,,,,,,,,,,,,,,,,135.022018432617,135.188385009766,499.652862548828,499.652862548828,,,12.6005125045776,-99999999,1,0,0,0,0.03204345703125,30.3030319213867,2,1,1,135.21826171875,0,3154121920,135.107162475586,,,0.00468614665751953,0.000226682230615784,0.00468596870076846,0.000226665972910424,0.961413741111755,0.962297201156616,31.6580543518066,0.186618611216545,60,1.1,200,0.00453024450689554,-1.60604405403137,0.542635500431061,1,,,,,,,,,,,,,,,,
,3739968692.72061,136.624732971191,499.652862548828,,,6,,,,31.6263326634739,,,10,,,,,,,,,,,,,,,,,,,,,,136.524917602539,136.693328857422,499.652862548828,499.652862548828,,,12.612322807312,-99999999,1,0,0,0,0.0247955322265625,30.3030319213867,2,1,1,136.724548339844,0,3154121920,136.605325317383,,,0.00307371134549979,0.000148665928336377,0.0030735837259223,0.000148653861681695,0.964730381965637,0.965871632099152,31.6607112884521,0.186596497893333,60,1.1,200,0.00184808543417603,-1.06439995765686,0.338655978441238,1,,,,,,,,,,,,,,,,
,3739968737.55828,138.121070861816,499.652862548828,,,6,,,,31.6313349000795,,,10,,,,,,,,,,,,,,,,,,,,,,138.01545715332,138.189193725586,499.652862548828,499.652862548828,,,12.6323471069336,-99999999,1,0,0,0,0.0225830078125,30.3030319213867,2,1,1,138.226684570312,0,3154121952,138.099609375,,,0.00212948885759365,0.000102986393619162,0.0021294041252922,0.000102978895894646,0.967730283737183,0.968769073486328,31.6627006530762,0.186571627855301,60,1.1,200,0.00132066081278026,-0.749524533748627,0.218349933624268,1,,,,,,,,,,,,,,,,
,3739968783.05592,139.623291015625,499.652862548828,,,6,,,,31.6313349000795,,,10,,,,,,,,,,,,,,,,,,,,,,139.517105102539,139.729476928711,499.652862548828,499.652862548828,,,12.6524667739868,-99999999,1,0,0,0,0.022430419921875,30.3030319213867,2,1,1,139.729476928711,0,3154121952,139.618927001953,,,0.00160886322444516,7.78054017443025E-5,0.00160880000333511,7.77990743097134E-5,0.968717813491821,0.970090270042419,31.6667175292969,0.186544001102448,60,1.1,200,0.000786723510827869,-0.576549768447876,0.152960807085037,1,,,,,,,,,,,,,,,,
,3739968828.2292,141.127914428711,499.652862548828,,,6,,,,31.6313349000795,,,10,,,,,,,,,,,,,,,,,,,,,,141.018768310547,141.200485229492,499.652862548828,499.652862548828,,,12.6854982376099,-99999999,1,0,0,0,0.0298309326171875,30.3030319213867,2,1,1,141.237060546875,0,3154121888,141.111444091797,,,0.00126080621902391,6.09718273792713E-5,0.00126075718598552,6.09665353650085E-5,0.969463169574738,0.971073031425476,31.6691055297852,0.186559826135635,60,1.1,200,0.000540595385245979,-0.46129909157753,0.109134398400784,1,,,,,,,,,,,,,,,,
,3739968873.06241,142.621948242188,499.652862548828,,,6,,,,31.6313349000795,,,10,,,,,,,,,,,,,,,,,,,,,,142.522232055664,142.689559936523,499.652862548828,499.652862548828,,,12.7166709899902,-99999999,1,0,0,0,0.0254058837890625,30.3030319213867,2,1,1,142.721664428711,0,3154121920,142.609906005859,,,0.00102326767399115,4.94837909871002E-5,0.00102322943094841,4.94792773299437E-5,0.969990909099579,0.971840739250183,31.6713733673096,0.186573714017868,60,1.1,200,0.000457595568150282,-0.382944673299789,0.079611249268055,1,,,,,,,,,,,,,,,,
,3739968918.26376,144.12720489502,499.652862548828,,,6,,,,31.636341788436,,,10,,,,,,,,,,,,,,,,,,,,,,144.018341064453,144.203598022461,499.652862548828,499.652862548828,,,12.7505578994751,-99999999,1,0,0,0,0.0223541259765625,30.3030319213867,2,1,1,144.236068725586,0,3154122080,144.110189819336,,,0.000846516166636142,4.09347460257508E-5,0.000846482516123508,4.09312056890185E-5,0.971321284770966,0.972998797893524,31.6736373901367,0.18655352294445,60,1.1,200,0.000297590246191248,-0.324451148509979,0.0574345923960209,1,,,,,,,,,,,,,,,,
,3739968963.6534,145.62223815918,499.652862548828,,,6,,,,31.636341788436,,,10,,,,,,,,,,,,,,,,,,,,,,145.523162841797,145.697891235352,499.652862548828,499.652862548828,,,12.7773933410645,-99999999,1,0,0,0,0.0214385986328125,30.3030319213867,2,1,1,145.721313476562,0,3154122240,145.610239664714,,,0.0007216673370286,3.48980097540678E-5,0.000721641624046635,3.48949291259728E-5,0.970783412456513,0.972643136978149,31.6759147644043,0.186547309160233,60,1.1,200,0.000418661336880177,-0.283997088670731,0.0419160015881062,1,,,,,,,,,,,,,,,,
,3739969008.26873,147.115303039551,499.652862548828,,,6,,,,31.636341788436,,,10,,,,,,,,,,,,,,,,,,,,,,147.017532348633,147.188217163086,499.652862548828,499.652862548828,,,12.8052291870117,-99999999,1,0,0,0,0.025482177734375,30.3030319213867,2,1,1,147.213073730469,0,3154121792,147.10458984375,,,0.00062462417943718,3.02044990200509E-5,0.000624601039621693,3.02015735191063E-5,0.971627950668335,0.973819196224213,31.6785144805908,0.186539590358734,60,1.1,200,0.000206605793209746,-0.251809895038605,0.0295999683439732,1,,,,,,,,,,,,,,,,
,3739969055.95903,148.693237304687,499.652862548828,,,6,,,,31.6413464393244,,,10,,,,,,,,,,,,,,,,,,,,,,148.584182739258,148.778610229492,499.652862548828,499.652862548828,,,12.8285074234009,-99999999,1,0,0,0,0.024261474609375,30.3030319213867,2,1,1,148.802291870117,0,3154122208,148.685971577962,,,0.000538140249643824,2.60186332233378E-5,0.000538151919165538,2.60173422777629E-5,0.977403163909912,0.980814695358276,31.6873588562012,0.18647013604641,60,1.1,200,-9.95655227598036E-6,-0.223578825592995,0.0188960153609514,1,,,,,,,,,,,,,,,,
,3739969150.86398,149.906242370605,499.652862548828,,,6,,,,31.6413464393244,,,10,,,,,,,,,,,,,,,,,,,,,,149.900772094727,149.910537719727,499.652862548828,499.652862548828,,,12.8619136810303,-99999999,1,0,0,0,0.0235748291015625,30.3030319213867,1,1,1,149.911712646484,0,3154122112,149.905935668945,,,0.00049145469579612,2.37643902079398E-5,0.000491436660457024,2.3762027213083E-5,0.972415030002594,0.974790155887604,31.6845111846924,0.186529457569122,60,1.1,200,0.00018542111502029,-0.208282485604286,0.0126576432958245,1,,,,,,,,,,,,,,,,
,3739969220.78579,152.817176818848,499.652862548828,,,6,,,,31.6413464393244,,,10,,,,,,,,,,,,,,,,,,,,,,152.509765625,153.02912902832,499.652862548828,499.652862548828,,,12.8766384124756,-99999999,1,0,0,0,0.0209808349609375,30.3030319213867,2,1,1,153.124588012695,0,3154121952,152.774310302734,,,0.000406913753608889,1.96775857684401E-5,0.000406899392106506,1.96755419901701E-5,0.970315039157867,0.972720682621002,31.6864547729492,0.186538383364677,60,1.1,200,0.000187171375728212,-0.181858703494072,0.00238105677999556,1,,,,,,,,,,,,,,,,
,3739969297.74638,160.452896118164,499.652862548828,,,6,,,,31.6513647307381,,,10,,,,,,,,,,,,,,,,,,,,,,160.127563476562,160.692153930664,499.652862548828,499.652862548828,,,12.8935022354126,-99999999,1,0,0,0,0.02655029296875,30.3030319213867,2,1,1,160.778228759766,0,3154122080,160.400747680664,,,0.000259568917587685,1.25504402898813E-5,0.000259574652785081,1.25498535532151E-5,0.975713193416595,0.978734314441681,31.6964836120605,0.186464622616768,60,1.1,200,7.75924945628503E-6,-0.133353784680367,-0.0158134121447802,1,,,,,,,,,,,,,,,,
,3739969371.50172,167.889495849609,499.652862548828,,,6,,,,31.656381162482,,,10,,,,,,,,,,,,,,,,,,,,,,167.571701049805,168.123718261719,499.652862548828,499.652862548828,,,12.9006643295288,-99999999,1,0,0,0,0.02716064453125,30.3030319213867,2,1,1,168.207290649414,0,3154121984,167.844686889648,,,0.00018710780042534,9.04830220972734E-6,0.000187100524785536,9.04751929696004E-6,0.969880104064941,0.971504330635071,31.6938743591309,0.186553761363029,60,1.1,200,1.42889784910949E-5,-0.109641186892986,-0.0249982643872499,1,,,,,,,,,,,,,,,,
,3739969455.49242,176.176071166992,499.652862548828,,,6,,,,31.6663980074952,,,1,,,,,,,,,,,,,,,,,,,,,,175.574203491211,176.696716308594,499.652862548828,499.652862548828,,,12.9049940109253,-99999999,1,0,0,0,0.025634765625,30.3030319213867,2,1,1,176.777938842773,0,3154122208,176.114947232333,,,0.000135540781600316,6.55430002656932E-6,0.000135542493165402,6.55399047109585E-6,0.971351683139801,0.973521649837494,31.7083225250244,0.186492174863815,60,1.1,200,-0.000305681314785033,-0.932132363319397,-0.0312382765114307,1,,,,,,,,,,,,,,,,
,3739969526.23953,183.21947479248,499.652862548828,,,6,,,,31.671782675836,,,1,,,,,,,,,,,,,,,,,,,,,,182.6181640625,183.732437133789,499.652862548828,499.652862548828,,,12.9207792282104,-99999999,1,0,0,0,0.02349853515625,30.3030319213867,2,1,1,183.820785522461,0,3154122048,183.165621948242,,,0.000108999582104081,5.27145070038235E-6,0.000109000941721549,5.27122595148402E-6,0.967663109302521,0.969412982463837,31.7119331359863,0.186516597867012,60,1.1,200,-0.000313712691422552,-0.845309674739838,-0.0347315557301044,1,,,,,,,,,,,,,,,,
,3739969598.06377,190.373443603516,499.652862548828,,,6,,,,31.6768153193568,,,1,,,,,,,,,,,,,,,,,,,,,,190.057281494141,190.588439941406,499.652862548828,499.652862548828,,,12.9388589859009,-99999999,1,0,0,0,0.02410888671875,30.3030319213867,2,1,1,190.689605712891,0,3154122080,190.313235473633,,,9.12108130869985E-5,4.41233157664931E-6,9.12073021533133E-5,4.41199868975755E-6,0.960235118865967,0.961174070835113,31.7096385955811,0.18660119175911,60,1.1,200,3.39945981977507E-5,-0.785643219947815,-0.370908558368683,1,,,,,,,,,,,,,,,,
,3739969673.06678,197.85538482666,499.652862548828,,,6,,,,31.6871141818524,,,1,,,,,,,,,,,,,,,,,,,,,,197.549728393555,198.073715209961,499.652862548828,499.652862548828,,,12.9806327819824,-99999999,1,0,0,0,0.021820068359375,30.3030319213867,2,1,1,198.161041259766,0,3154122112,197.822445678711,,,7.63711762339629E-5,3.69501581269596E-6,7.63682439049821E-5,3.69477048500127E-6,0.956632077693939,0.957281410694122,31.715633392334,0.186635091900826,60,1.1,200,8.52050652611069E-5,-0.738365948200226,-0.390863448381424,1,,,,,,,,,,,,,,,,
,3739969748.64915,205.385444641113,499.652862548828,,,6,,,,31.6971753479253,,,1,,,,,,,,,,,,,,,,,,,,,,205.06266784668,205.615570068359,499.652862548828,499.652862548828,,,13.0249338150024,-99999999,1,0,0,0,0.0231170654296875,30.3030319213867,2,1,1,205.708221435547,0,3154121920,205.326953125,,,6.49472139029655E-5,3.14319486312253E-6,6.49449336397121E-5,3.1430269440747E-6,0.950501322746277,0.950871825218201,31.7201805114746,0.186693966388702,60,1.1,200,0.000164383687661029,-0.703378081321716,-0.406611293554306,1,,,,,,,,,,,,,,,,
,3739969823.69429,212.8701171875,499.652862548828,,,6,,,,31.7071844222947,,,1,,,,,,,,,,,,,,,,,,,,,,212.570404052734,213.078308105469,499.652862548828,499.652862548828,,,13.0700769424438,-99999999,1,0,0,0,0.0252532958984375,30.3030319213867,2,1,1,213.169830322266,0,3154122112,212.804837036133,,,5.61830002260086E-5,2.71983618690417E-6,5.61811927776589E-5,2.71971139639426E-6,0.944921731948852,0.945170521736145,31.72705078125,0.186754569411278,60,1.1,200,0.000133803929202259,-0.675474524497986,-0.417717427015305,1,,,,,,,,,,,,,,,,
,3739969899.16867,220.376358032227,499.652862548828,,,6,,,,31.7172132654021,,,1,,,,,,,,,,,,,,,,,,,,,,220.047271728516,220.594390869141,499.652862548828,499.652862548828,,,13.1125717163086,-99999999,1,0,0,0,0.019989013671875,30.3030319213867,2,1,1,220.719879150391,0,3154121952,220.323034667969,,,4.90929369666916E-5,2.37735987034025E-6,4.90916627709152E-5,2.37728207052402E-6,0.939439058303833,0.939550578594208,31.7311401367188,0.186792463064194,60,1.1,200,-0.000115511968033388,-0.653316676616669,-0.427705973386765,1,,,,,,,,,,,,,,,,
,3739969974.55529,227.864364624023,499.652862548828,,,6,,,,31.7273064254899,,,1,,,,,,,,,,,,,,,,,,,,,,227.574462890625,228.083847045898,499.652862548828,499.652862548828,,,13.1755037307739,-99999999,1,0,0,0,0.0180816650390625,30.3030319213867,2,1,1,228.168960571289,0,3154122176,227.820571899414,,,4.33011344545103E-5,2.09816626233391E-6,4.32999076421857E-5,2.09808808696086E-6,0.930136144161224,0.93026340007782,31.7432460784912,0.186916902661324,60,1.1,200,-0.000261370150838047,-0.635953187942505,-0.43549981713295,1,,,,,,,,,,,,,,,,
,3739970055.62284,235.94702911377,499.652862548828,,,6,,,,31.7426317058797,,,1,,,,,,,,,,,,,,,,,,,,,,235.338592529297,236.477600097656,499.652862548828,499.652862548828,,,13.2619972229004,-99999999,1,0,0,0,0.017242431640625,30.3030319213867,2,1,1,236.555465698242,0,3154122112,235.879676125266,,,3.79381099081257E-5,1.83944055105027E-6,3.79380429087351E-5,1.8394275498437E-6,0.92179799079895,0.921865403652191,31.7548732757568,0.186971962451935,60,1.1,200,0.000232769918511622,-0.619981348514557,-0.0445012785494328,1,,,,,,,,,,,,,,,,
,3739970128.62683,243.249137878418,499.652862548828,,,6,,,,31.7526499505893,,,1,,,,,,,,,,,,,,,,,,,,,,242.618179321289,243.807052612305,499.652862548828,499.652862548828,,,13.3347778320312,-99999999,1,0,0,0,0.0220489501953125,30.3030319213867,2,1,1,243.880096435547,0,3154122176,243.193030617454,,,3.40605644109052E-5,1.65256744976883E-6,3.40605408342302E-5,1.65255794088232E-6,0.913542807102203,0.913600921630859,31.7645778656006,0.18708823621273,60,1.1,200,0.000184204633114859,-0.609476864337921,-0.0450865961611271,1,,,,,,,,,,,,,,,,
,3739970204.06609,250.717491149902,499.652862548828,,,6,,,,31.7631954657978,,,1,,,,,,,,,,,,,,,,,,,,,,250.110717773438,251.215469360352,499.652862548828,499.652862548828,,,13.3989686965942,-99999999,1,0,0,0,0.0171661376953125,30.3030319213867,2,1,1,251.324264526367,0,3154122176,250.65570900657,,,3.06846617551049E-5,1.4899563635811E-6,3.06846351706806E-5,1.48995336974706E-6,0.90486866235733,0.904880583286285,31.7688465118408,0.18725511431694,60,1.1,200,-0.000423525983933359,-0.600256383419037,-0.0457342006266117,1,,,,,,,,,,,,,,,,
,3739970275.8499,257.870468139648,499.652862548828,,,6,,,,31.7734289287594,,,1,,,,,,,,,,,,,,,,,,,,,,257.584167480469,258.070953369141,499.652862548828,499.652862548828,,,13.4274559020996,-99999999,1,0,0,0,0.02288818359375,30.3030319213867,2,1,1,258.156768798828,0,3154120736,257.824981689453,,,2.80467920518864E-5,1.36331074047937E-6,2.80470561314551E-5,1.36332287757057E-6,0.894433975219727,0.894438743591309,31.7696533203125,0.187482967972755,60,1.1,200,0.000121487770229578,-0.594496846199036,-0.462002784013748,1,,,,,,,,,,,,,,,,
,3739970355.50294,265.761627197266,499.652862548828,,,6,,,,31.7898125113115,,,1,,,,,,,,,,,,,,,,,,,,,,265.122222900391,266.401031494141,499.652862548828,499.652862548828,,,13.4988136291504,-99999999,1,0,0,0,0.0231170654296875,30.3030319213867,2,1,1,266.401031494141,0,3154122208,265.771018288352,,,2.52972416409575E-5,1.23172264081225E-6,2.52972925634043E-5,1.23172488486973E-6,0.879775643348694,0.879777252674103,31.7875194549561,0.187769085168838,60,1.1,200,6.43028834019788E-5,-0.579980969429016,-0.046162310987711,1,,,,,,,,,,,,,,,,
,3739970425.14581,272.87565612793,499.652862548828,,,6,,,,31.7998477141373,,,1,,,,,,,,,,,,,,,,,,,,,,272.556243896484,273.10302734375,499.652862548828,499.652862548828,,,13.5146827697754,-99999999,1,0,0,0,0.0197601318359375,30.3030319213867,2,1,1,273.195068359375,0,3154122176,272.832403564453,,,2.3379178160141E-5,1.13894165918414E-6,2.33798414692815E-5,1.1389665226963E-6,0.875461757183075,0.87551349401474,31.7864570617676,0.187884405255318,60,1.1,200,-0.000352405331796035,-0.576545298099518,-0.465093672275543,1,,,,,,,,,,,,,,,,
,3739970504.22136,280.728576660156,499.652862548828,,,6,,,,31.8157998018458,,,1,,,,,,,,,,,,,,,,,,,,,,280.112731933594,281.27978515625,499.652862548828,499.652862548828,,,13.535138130188,-99999999,1,0,0,0,0.0037384033203125,30.3030319213867,2,1,1,281.344421386719,0,3154122208,280.715899658203,,,2.10536085780874E-5,1.02771580198391E-6,2.10538863433466E-5,1.02772165410845E-6,0.86048299074173,0.860535681247711,31.8015365600586,0.188226237893105,60,1.1,200,-0.000239524772041477,-0.574513077735901,-0.0474694408476353,1,,,,,,,,,,,,,,,,
,3739970584.0709,288.618041992188,499.652862548828,,,6,,,,31.8308541784977,,,1,,,,,,,,,,,,,,,,,,,,,,287.999786376953,289.168029785156,499.652862548828,499.652862548828,,,13.5632705688477,-99999999,1,0,0,0,0.0028228759765625,30.3030319213867,2,1,1,289.236297607422,0,3154122048,288.61509288441,,,1.92741673184248E-5,9.42629762159555E-7,1.92747681541456E-5,9.4263358398175E-7,0.847830295562744,0.848004460334778,31.8038349151611,0.188564151525497,60,1.1,200,0.000366381980711594,-0.571136593818665,-0.0479977615177631,1,,,,,,,,,,,,,,,,
,3739970655.68845,295.715789794922,499.652862548828,,,6,,,,31.8428298988129,,,1,,,,,,,,,,,,,,,,,,,,,,295.111541748047,296.230804443359,499.652862548828,499.652862548828,,,13.596658706665,-99999999,1,0,0,0,0.018768310546875,30.3030319213867,2,1,1,296.320037841797,0,3154122112,295.690087890625,,,1.78979437320541E-5,8.77257128615473E-7,1.78989861797657E-5,8.77256383662696E-7,0.834296464920044,0.834643661975861,31.8031330108643,0.188991218805313,60,1.1,200,-0.000472624698886648,-0.568564295768738,-0.0482930280268192,1,,,,,,,,,,,,,,,,
,3739970774.17616,299.926055908203,499.652862548828,,,6,,,,31.8478578537684,,,1,,,,,,,,,,,,,,,,,,,,,,299.922912597656,299.928833007812,499.652862548828,499.652862548828,,,13.6549711227417,-99999999,1,0,0,0,0.01953125,30.3030319213867,1,1,1,299.92919921875,0,3154122048,299.926678466797,,,1.70168457432127E-5,8.35761024121136E-7,1.70173994136595E-5,8.35770605404487E-7,0.822836339473724,0.822951555252075,31.8242263793945,0.189396888017654,60,1.1,200,8.81371943250997E-6,-0.568011522293091,-0.484843820333481,1,,,,,,,,,,,,,,,,