File: Observation of a Zero-Field Josephson Diode Effect in a Helimagnet Josephson Junction/Figure 1/Magnetic Characterization/CNS_KL180615_003_abplane_001.dat
[Header]
; MPMS3 Data File (default extension .dat)
; Copyright (c) 2007, Quantum Design, Inc. All rights reserved.
TITLE,CNS_KL180529_003_abplane
FILEOPENTIME,3739955473.54673,07/05/2018,12:33 pm
BYAPP,SQUID AC,0.9.1.0
INFO,MPMS3 Measurement Release 1.1.16 Build 347, MultiVu Release 2.3.3.2,APPNAME
INFO,1,MOMENT_UNITS
INFO,CrNb3S6,SAMPLE_MATERIAL
INFO,003 abplane,SAMPLE_COMMENT
INFO,,SAMPLE_MASS
INFO,,SAMPLE_VOLUME
INFO,,SAMPLE_MOLECULAR_WEIGHT
INFO,,SAMPLE_SIZE
INFO,disk,SAMPLE_SHAPE
INFO,Quartz,SAMPLE_HOLDER
INFO,Standard,SAMPLE_HOLDER_DETAIL
INFO,67.1,SAMPLE_OFFSET
DATATYPE,COMMENT,1
DATATYPE,TIME,2
STARTUPAXIS,X,2
STARTUPAXIS,Y1,5
FIELDGROUP, VSM,2,3,4,5,6,8,9,10,11,14,15
FIELDGROUP, DC, 2,3,4,14,56,57,58,59,60,61,62,63,64,65,66,67,68,69
FIELDGROUP, AC, 2,3,4,11,16,17,18,19,20,21,22,23,24,25,26,27,28,29,30
STARTUPGROUP, All
[Data]
Comment,Time Stamp (sec),Temperature (K),Magnetic Field (Oe),Moment (Am2),M. Std. Err. (Am2),Transport Action,Averaging Time (sec),Frequency (Hz),Peak Amplitude (mm),Center Position (mm),Lockin Signal' (V),Lockin Signal (V),Range,M. Quad. Signal (Am2),AC Moment (Am2),AC M. Std Err. (Am2),AC Phase (deg),AC Phase Std. Err. (deg),AC Susceptibility (Am2/T),AC Suscept. Std Err. (Am2/T),AC X' (Am2/T),AC X' Std Err. (Am2/T),AC X'' (Am2/T),AC X'' Std Err. (Am2/T),AC Drive (T),AC Frequency (Hz),AC Averaging Time (sec),AC Cycles,AC Range,AC Measure Type,AC Signal' (V),AC Signal'' (V),AC Trim Coil Ratio,AC Trim Coil Phase,Min. Temperature (K),Max. Temperature (K),Min. Field (Oe),Max. Field (Oe),Mass (grams),Motor Lag (deg),Pressure (Torr),Measure Count,Measurement Number,SQUID Status (code),Motor Status (code),Measure Status (code),Motor Current (amps),Motor Temp. (C),Temp. Status (code),Field Status (code),Chamber Status (code),Chamber Temp (K),Redirection State,Evercool Status,Average Temp (K),Rotation Angle (deg),Rotator state,DC Moment Fixed Ctr (emu),DC Moment Err Fixed Ctr (emu),DC Moment Free Ctr (emu),DC Moment Err Free Ctr (emu),DC Fixed Fit,DC Free Fit,DC Calculated Center (mm),DC Calculated Center Err (mm),DC Scan Length (mm),DC Scan Time (s),DC Number of Points,DC Squid Drift,DC Min V (V),DC Max V (V),DC Scans per Measure,Map 01,Map 02,Map 03,Map 04,Map 05,Map 06,Map 07,Map 08,Map 09,Map 10,Map 11,Map 12,Map 13,Map 14,Map 15,Map 16
,3739958828.2272,2.0009331703186,499.652862548828,,,6,,,,31.5663820827955,,,10,,,,,,,,,,,,,,,,,,,,,,1.99854159355164,2.00113344192505,499.652862548828,499.652862548828,,,2.80864691734314,-99999999,1,0,0,0,0.012969970703125,30.3030319213867,1,1,1,2.00073289871216,0,3154122016,2.0000322943642,,,0.00992085157097954,0.000494873768296531,0.00992212031859038,0.000494876936199308,0.983575463294983,0.994818687438965,31.6254653930664,0.188845321536064,30,4,200,0.00266027706675231,-4.22126531600952,4.8427209854126,1,,,,,,,,,,,,,,,,
,3739958896.24023,6.50830864906311,499.652862548828,,,6,,,,31.5663820827955,,,10,,,,,,,,,,,,,,,,,,,,,,6.00700902938843,6.95826244354248,499.652862548828,499.652862548828,,,4.9725341796875,-99999999,1,0,0,0,0,30.3030319213867,6,1,1,7.00960826873779,0,3154122272,6.49344305558638,,,0.00992256139417844,0.000494960151780724,0.00992386445769196,0.000494963168807339,0.983445107936859,0.995135426521301,31.6263580322266,0.188845217227936,30,4,200,0.00292668794281781,-3.88600707054138,0.539764046669006,1,,,,,,,,,,,,,,,,
,3739958961.2267,12.5238656997681,499.652862548828,,,6,,,,31.5663820827955,,,10,,,,,,,,,,,,,,,,,,,,,,12.0139036178589,12.9972972869873,499.652862548828,499.652862548828,,,6.72458600997925,-99999999,1,0,0,0,0,30.3030319213867,6,1,1,13.0338277816772,0,3154122176,12.5117193568837,,,0.00990220405616379,0.000493946519050575,0.00990353530874598,0.000493948867768218,0.983229219913483,0.995315372943878,31.6274127960205,0.188848108053207,30,4,200,0.00277861673384905,-3.87969970703125,0.536771476268768,1,,,,,,,,,,,,,,,,
,3739959023.28884,18.5350694656372,499.652862548828,,,6,,,,31.5663820827955,,,10,,,,,,,,,,,,,,,,,,,,,,18.003360748291,19.0128211975098,499.652862548828,499.652862548828,,,7.27216386795044,-99999999,1,0,0,0,0,30.3030319213867,2,1,1,19.0667781829834,0,3154121888,18.526932629672,,,0.0098704108233444,0.000492362802099815,0.00987180437948142,0.00049236596455703,0.982954084873199,0.99540650844574,31.6285915374756,0.188834428787231,30,4,200,0.00247399625368416,-3.87198996543884,0.530813872814178,1,,,,,,,,,,,,,,,,
,3739959086.46818,24.5470209121704,499.652862548828,,,6,,,,31.5663820827955,,,10,,,,,,,,,,,,,,,,,,,,,,24.0167446136475,25.00830078125,499.652862548828,499.652862548828,,,7.59248352050781,-99999999,1,0,0,0,0,30.3030319213867,2,1,1,25.0772972106934,0,3154122176,24.5180325941606,,,0.00982287175078567,0.000489994205834911,0.00982430274241964,0.000489997029352845,0.982628762722015,0.995310485363007,31.6297760009766,0.188849002122879,30,4,200,0.0026761966291815,-3.85882544517517,0.522862374782562,1,,,,,,,,,,,,,,,,
,3739959157.92286,31.3601131439209,499.652862548828,,,6,,,,31.5713845451493,,,10,,,,,,,,,,,,,,,,,,,,,,30.3059959411621,32.3648834228516,499.652862548828,499.652862548828,,,7.86139154434204,-99999999,1,0,0,0,0.012969970703125,30.3030319213867,2,1,1,32.4142303466797,0,3154122048,31.3409430185954,,,0.0097506258825594,0.000486385195777668,0.00975194203417176,0.00048638796120161,0.98326963186264,0.995377004146576,31.6323204040527,0.188839718699455,30,4,200,0.00243158545345068,-4.68198204040527,4.87223100662231,1,,,,,,,,,,,,,,,,
,3739959212.58313,36.5542945861816,499.652862548828,,,6,,,,31.5713845451493,,,10,,,,,,,,,,,,,,,,,,,,,,36.0191802978516,37.0468597412109,499.652862548828,499.652862548828,,,7.97834491729736,-99999999,1,0,0,0,0,30.3030319213867,2,1,1,37.0894088745117,0,3154122048,36.5433724143288,,,0.00969333140134012,0.000483529554729473,0.00969468224234791,0.000483532115166202,0.982964754104614,0.99529504776001,31.6334362030029,0.188841819763184,30,4,200,0.00253106048330665,-3.81949305534363,0.505085706710815,1,,,,,,,,,,,,,,,,
,3739959275.19462,42.5619735717773,499.652862548828,,,6,,,,31.5713845451493,,,10,,,,,,,,,,,,,,,,,,,,,,42.0149688720703,43.0186195373535,499.652862548828,499.652862548828,,,8.11556434631348,-99999999,1,0,0,0,0,30.3030319213867,2,1,1,43.1089782714844,0,3154122144,42.5163438970392,,,0.00960541085796169,0.000479149016475816,0.00960685629424487,0.000479151746294648,0.982340693473816,0.995272040367127,31.6358680725098,0.188838243484497,30,4,200,0.0025421844329685,-3.79101872444153,0.494910776615143,1,,,,,,,,,,,,,,,,
,3739959337.24155,48.5479698181152,499.652862548828,,,6,,,,31.5713845451493,,,10,,,,,,,,,,,,,,,,,,,,,,48.0119934082031,49.0162734985352,499.652862548828,499.652862548828,,,8.24812602996826,-99999999,1,0,0,0,0,30.3030319213867,2,1,1,49.0839462280273,0,3154122272,48.5344592007724,,,0.00950285905227804,0.000474040016274509,0.00950441843535569,0.000474042626725309,0.981573581695557,0.99526309967041,31.6388740539551,0.188845321536064,30,4,200,0.0023493233602494,-3.75860643386841,0.481816828250885,1,,,,,,,,,,,,,,,,
,3739959402.81705,54.9065608978271,499.652862548828,,,6,,,,31.5763866625619,,,10,,,,,,,,,,,,,,,,,,,,,,54.3821792602539,55.3935432434082,499.652862548828,499.652862548828,,,8.41200542449951,-99999999,1,0,0,0,0,30.3030319213867,2,1,1,55.4309425354004,0,3154122112,54.8896997625178,,,0.00938443612016915,0.000468131485673195,0.00938596856159547,0.000468134937802637,0.981699049472809,0.995187163352966,31.643310546875,0.188856393098831,30,4,200,0.00224524457007647,-3.72163534164429,0.466624975204468,1,,,,,,,,,,,,,,,,
,3739959461.13372,60.5616798400879,499.652862548828,,,6,,,,31.5763866625619,,,10,,,,,,,,,,,,,,,,,,,,,,60.033821105957,61.0386428833008,499.652862548828,499.652862548828,,,8.59565734863281,-99999999,1,0,0,0,0,30.3030319213867,2,1,1,61.0895385742188,0,3154122080,60.5302689292214,,,0.00926352283421011,0.000462106043135564,0.00926515817588876,0.000462109456383933,0.980990469455719,0.99518746137619,31.6460876464844,0.188848793506622,30,4,200,0.00215411209501326,-3.68025207519531,0.55971771478653,1,,,,,,,,,,,,,,,,
,3739959530.94035,67.331169128418,499.652862548828,,,6,,,,31.5815662517272,,,10,,,,,,,,,,,,,,,,,,,,,,66.2416687011719,68.3649215698242,499.652862548828,499.652862548828,,,8.93867015838623,-99999999,1,0,0,0,0,30.3030319213867,2,1,1,68.4206695556641,0,3154122144,67.3204585484096,,,0.00908830245934449,0.000453364139902631,0.0090898649699984,0.000453366400815031,0.981138646602631,0.995313227176666,31.6508121490479,0.188862100243568,30,4,200,0.00204632594250143,-4.57493305206299,4.86391973495483,1,,,,,,,,,,,,,,,,
,3739959584.84506,72.5603523254394,499.652862548828,,,6,,,,31.5815662517272,,,10,,,,,,,,,,,,,,,,,,,,,,72.0227355957031,73.0675354003906,499.652862548828,499.652862548828,,,9.19655418395996,-99999999,1,0,0,0,0,30.3030319213867,2,1,1,73.0979690551758,0,3154122176,72.5551341663707,,,0.00897284694372769,0.000447609592617553,0.00897449915924575,0.000447612345330026,0.980554461479187,0.995281577110291,31.6530685424805,0.188870936632156,30,4,200,0.00203417520970106,-3.48297262191772,0.52273815870285,1,,,,,,,,,,,,,,,,
,3739959654.03377,79.2875900268555,499.652862548828,,,6,,,,31.5868340316961,,,10,,,,,,,,,,,,,,,,,,,,,,78.2297744750977,80.2736129760742,499.652862548828,499.652862548828,,,9.33800029754639,-99999999,1,0,0,0,0,30.3030319213867,2,1,1,80.3454055786133,0,3154122176,79.2418038504464,,,0.00876642370443314,0.000437312409557265,0.00876805290765811,0.000437315475925325,0.980505347251892,0.995258748531342,31.6585006713867,0.188855811953545,30,4,200,0.00193669064901769,-4.693274974823,4.87366724014282,1,,,,,,,,,,,,,,,,
,3739959708.18215,84.5895156860352,499.652862548828,,,6,,,,31.5868340316961,,,10,,,,,,,,,,,,,,,,,,,,,,84.0401992797852,85.0958480834961,499.652862548828,499.652862548828,,,9.38847541809082,-99999999,1,0,0,0,0.00213623046875,30.3030319213867,2,1,1,85.1388320922852,0,3154122176,84.5819230513139,,,0.0086138210448713,0.000429706862422651,0.00861555829741281,0.000429709994925829,0.979709923267364,0.995201170444489,31.6615581512451,0.188867077231407,30,4,200,0.00187423021998256,-3.36892414093018,0.47796043753624,1,,,,,,,,,,,,,,,,
,3739959838.12735,89.9645957946777,499.652862548828,,,6,,,,31.5918417152695,,,10,,,,,,,,,,,,,,,,,,,,,,89.9568481445313,89.9715270996094,499.652862548828,499.652862548828,,,9.47957420349121,-99999999,1,0,0,0,0,30.3030319213867,1,1,1,89.9723434448242,0,3154122048,89.9646044644442,,,0.00843495964385137,0.000420787034346977,0.00843672903783247,0.000420790425675226,0.979376375675201,0.99530440568924,31.6679553985596,0.188862219452858,30,4,200,0.00207266910001636,-3.30923295021057,0.453614592552185,1,,,,,,,,,,,,,,,,
,3739959897.83105,90.6044540405273,499.652862548828,,,6,,,,31.5918417152695,,,10,,,,,,,,,,,,,,,,,,,,,,90.5152282714844,90.6686096191406,499.652862548828,499.652862548828,,,9.53712749481201,-99999999,1,0,0,0,0.034637451171875,30.3030319213867,2,1,1,90.6936798095703,0,3154122208,90.5932312011719,,,0.00841802822729725,0.000407112333671617,0.00841816662259948,0.000407044470408097,0.967767417430878,0.974058628082275,31.6657257080078,0.186534628272057,60,1.1,200,0.000240946057601832,-2.86996102333069,0.993904709815979,1,,,,,,,,,,,,,,,,
,3739959944.9891,92.1357574462891,499.652862548828,,,6,,,,31.5918417152695,,,10,,,,,,,,,,,,,,,,,,,,,,92.0269241333008,92.2393341064453,499.652862548828,499.652862548828,,,9.57865142822266,-99999999,1,0,0,0,0.0283050537109375,30.3030319213867,2,1,1,92.2445907592773,0,3154121952,92.132069905599,,,0.00836300611738356,0.000404458193291378,0.0083632114338268,0.000404386062335852,0.967243492603302,0.97416341304779,31.6696224212646,0.18653379380703,60,1.1,200,0.00161724386271089,-2.85235548019409,0.988447308540344,1,,,,,,,,,,,,,,,,
,3739959989.95251,93.6299629211426,499.652862548828,,,6,,,,31.5918417152695,,,10,,,,,,,,,,,,,,,,,,,,,,93.5235061645508,93.7364196777344,499.652862548828,499.652862548828,,,9.59997367858887,-99999999,1,0,0,0,0.022125244140625,30.3030319213867,2,1,1,93.7364196777344,0,3154653248,93.6335754394531,,,0.00831664110655392,0.000402213825477517,0.00831682254293121,0.000402142648339941,0.967397272586823,0.974198997020721,31.6688461303711,0.186557710170746,60,1.1,200,0.0032410800922662,-2.83917570114136,0.980251312255859,1,,,,,,,,,,,,,,,,
,3739960034.71486,95.1175880432129,499.652862548828,,,6,,,,31.5968627693913,,,10,,,,,,,,,,,,,,,,,,,,,,95.0022430419922,95.2329330444336,499.652862548828,499.652862548828,,,9.63414764404297,-99999999,1,0,0,0,0.0262451171875,30.3030319213867,2,1,1,95.2329330444336,0,3154122336,95.1270434061686,,,0.00826078094745638,0.000399504406381741,0.00826085772625011,0.000399437539006873,0.968003332614899,0.974101841449738,31.6694583892822,0.186556428670883,60,1.1,200,0.000702605175320059,-2.81267976760864,0.972661316394806,1,,,,,,,,,,,,,,,,
,3739960080.63219,96.6232757568359,499.652862548828,,,6,,,,31.5968627693913,,,10,,,,,,,,,,,,,,,,,,,,,,96.523307800293,96.7232437133789,499.652862548828,499.652862548828,,,9.65090560913086,-99999999,1,0,0,0,0.0331878662109375,30.3030319213867,2,1,1,96.7232437133789,0,3154122080,96.6203536987305,,,0.00820915654480497,0.000397011760018296,0.00820928377112478,0.000396941837701277,0.967694222927094,0.974295556545258,31.6724681854248,0.186554566025734,60,1.1,200,0.00272616627626121,-2.79840922355652,0.966700792312622,1,,,,,,,,,,,,,,,,
,3739960125.59195,98.1215209960937,499.652862548828,,,6,,,,31.5968627693913,,,10,,,,,,,,,,,,,,,,,,,,,,98.0241165161133,98.2189254760742,499.652862548828,499.652862548828,,,9.6756534576416,-99999999,1,0,0,0,0.0246429443359375,30.3030319213867,2,1,1,98.2189254760742,0,3154122016,98.1209386189779,,,0.00815580268578555,0.000394433669620328,0.00815594745360457,0.000394364059321174,0.967518925666809,0.974176347255707,31.6729755401611,0.186547517776489,60,1.1,200,0.000178008325747214,-2.78228735923767,0.960419774055481,1,,,,,,,,,,,,,,,,
,3739960170.66362,99.6244316101074,499.652862548828,,,6,,,,31.5968627693913,,,10,,,,,,,,,,,,,,,,,,,,,,99.5189208984375,99.7265243530273,499.652862548828,499.652862548828,,,9.70935440063477,-99999999,1,0,0,0,0.0255584716796875,30.3030319213867,2,1,1,99.7299423217773,0,3154121984,99.6235847473145,,,0.00809766048954015,0.000391626901684468,0.00809788112031167,0.000391555736129345,0.967124223709106,0.974246919155121,31.6758079528809,0.186555042862892,60,1.1,200,0.000752992287743837,-2.76327157020569,0.954629421234131,1,,,,,,,,,,,,,,,,
,3739960216.05945,101.13883972168,499.652862548828,,,6,,,,31.6018643291032,,,10,,,,,,,,,,,,,,,,,,,,,,101.039512634277,101.238166809082,499.652862548828,499.652862548828,,,9.74143218994141,-99999999,1,0,0,0,0.0299835205078125,30.3030319213867,2,1,1,101.238166809082,0,3154122176,101.132488250732,,,0.0080318723018578,0.00038839284445351,0.00803261621548262,0.000388348386423806,0.971509993076324,0.98005622625351,31.6804466247559,0.186519578099251,60,1.1,200,0.000970788823906332,-2.74822568893433,0.945797443389893,1,,,,,,,,,,,,,,,,
,3739960260.80639,102.622894287109,499.652862548828,,,6,,,,31.6018643291032,,,10,,,,,,,,,,,,,,,,,,,,,,102.526214599609,102.684707641602,499.652862548828,499.652862548828,,,9.77436256408691,-99999999,1,0,0,0,0.033721923828125,30.3030319213867,2,1,1,102.719573974609,0,3154122240,102.599462890625,,,0.00799598497335597,0.000386702383673313,0.00799612446294716,0.000386634779084111,0.967704772949219,0.974334001541138,31.6775989532471,0.18656513094902,60,1.1,200,0.000328411435475573,-2.73165321350098,0.939312219619751,1,,,,,,,,,,,,,,,,
,3739960305.96057,104.119358062744,499.652862548828,,,6,,,,31.6018643291032,,,10,,,,,,,,,,,,,,,,,,,,,,104.019172668457,104.219543457031,499.652862548828,499.652862548828,,,9.81125259399414,-99999999,1,0,0,0,0.0258636474609375,30.3030319213867,2,1,1,104.219543457031,0,3154122176,104.118312835693,,,0.00794154537487189,0.000384073072438635,0.00794172797903696,0.00038400473001562,0.967409074306488,0.97429758310318,31.6792793273926,0.186551958322525,60,1.1,200,-0.000136021015350707,-2.60443305969238,0.936462223529816,1,,,,,,,,,,,,,,,,
,3739960350.9971,105.622676849365,499.652862548828,,,6,,,,31.6018643291032,,,10,,,,,,,,,,,,,,,,,,,,,,105.525924682617,105.701622009277,499.652862548828,499.652862548828,,,9.83988857269287,-99999999,1,0,0,0,0.0305938720703125,30.3030319213867,2,1,1,105.719429016113,0,3154122080,105.614327748617,,,0.00788515275460094,0.00038134295645467,0.0078853007861804,0.000381274814821689,0.967640519142151,0.974455654621124,31.6786155700684,0.18656113743782,60,1.1,200,0.00117815274279565,-2.58745002746582,0.928347289562225,1,,,,,,,,,,,,,,,,
,3739960400.57996,107.270191192627,499.652862548828,,,6,,,,31.6068651893466,,,10,,,,,,,,,,,,,,,,,,,,,,107.163063049316,107.377319335938,499.652862548828,499.652862548828,,,9.88583087921143,-99999999,1,0,0,0,0.029144287109375,30.3030319213867,2,1,1,107.377319335938,0,3154121952,107.271806081136,,,0.00780656125260819,0.000377492463777787,0.00780732101493254,0.000377451876459061,0.971991658210754,0.98063462972641,31.6850090026855,0.186488568782806,60,1.1,200,0.000332319032168016,-2.56733584403992,0.918684005737305,1,,,,,,,,,,,,,,,,
,3739960441.17641,108.621231079102,499.652862548828,,,6,,,,31.6068651893466,,,10,,,,,,,,,,,,,,,,,,,,,,108.518615722656,108.692687988281,499.652862548828,499.652862548828,,,9.90201759338379,-99999999,1,0,0,0,0.028533935546875,30.3030319213867,2,1,1,108.723846435547,0,3154122016,108.608174133301,,,0.00777291435702801,0.00037591236407017,0.00777302846688903,0.000375845859627692,0.967837572097778,0.974475085735321,31.6824607849121,0.186547711491585,60,1.1,200,0.00124253006651998,-2.55051255226135,0.914432644844055,1,,,,,,,,,,,,,,,,
,3739960486.50842,110.131790161133,499.652862548828,,,6,,,,31.6068651893466,,,10,,,,,,,,,,,,,,,,,,,,,,110.018341064453,110.221366882324,499.652862548828,499.652862548828,,,9.94152069091797,-99999999,1,0,0,0,0.0292205810546875,30.3030319213867,2,1,1,110.245239257813,0,3154122208,110.121063232422,,,0.00771972265132088,0.000373342395449687,0.00771989196251562,0.000373278221182859,0.967643976211548,0.974317967891693,31.6829071044922,0.18656824529171,60,1.1,200,0.00154740922152996,-2.53468894958496,0.908327341079712,1,,,,,,,,,,,,,,,,
,3739960531.38567,111.624324798584,499.652862548828,,,6,,,,31.6068651893466,,,10,,,,,,,,,,,,,,,,,,,,,,111.51806640625,111.703834533691,499.652862548828,499.652862548828,,,9.97517871856689,-99999999,1,0,0,0,0.031280517578125,30.3030319213867,2,1,1,111.730583190918,0,3154122112,111.608811950684,,,0.00766171282576477,0.000370538436966375,0.00766188707426122,0.000370470878729738,0.967506527900696,0.974583327770233,31.685079574585,0.186566159129143,60,1.1,200,0.00120538100600243,-2.51426839828491,0.899834394454956,1,,,,,,,,,,,,,,,,
,3739960576.67185,113.121509552002,499.652862548828,,,6,,,,31.6068651893466,,,10,,,,,,,,,,,,,,,,,,,,,,113.023643493652,113.195175170898,499.652862548828,499.652862548828,,,10.0026149749756,-99999999,1,0,0,0,0.0278472900390625,30.3030319213867,2,1,1,113.219375610352,0,3154122016,113.111703236898,,,0.00760695240754,0.000367894289814109,0.00760717513156758,0.000367824964756279,0.967169225215912,0.974647164344788,31.6874523162842,0.186555907130241,60,1.1,200,0.0012147210072726,-2.49720501899719,0.893133938312531,1,,,,,,,,,,,,,,,,
,3739960621.97955,114.627223968506,499.652862548828,,,6,,,,31.6118758000877,,,10,,,,,,,,,,,,,,,,,,,,,,114.523941040039,114.695915222168,499.652862548828,499.652862548828,,,10.0430421829224,-99999999,1,0,0,0,0.02899169921875,30.3030319213867,2,1,1,114.730506896973,0,3154121824,114.612812805176,,,0.00755358559280144,0.000365304701430767,0.0075537260479753,0.000365240630261426,0.967897057533264,0.974644124507904,31.6879444122314,0.186555802822113,60,1.1,200,0.000837994564790279,-2.48282384872437,0.885659754276276,1,,,,,,,,,,,,,,,,
,3739960667.1579,116.118713378906,499.652862548828,,,6,,,,31.6118758000877,,,10,,,,,,,,,,,,,,,,,,,,,,116.020492553711,116.185623168945,499.652862548828,499.652862548828,,,10.0756568908691,-99999999,1,0,0,0,0.0356292724609375,30.3030319213867,2,1,1,116.216934204102,0,3154122208,116.100726318359,,,0.00749823983162864,0.000362636065588545,0.00749847313915732,0.000362569067865098,0.967227637767792,0.974649846553802,31.6921348571777,0.186572477221489,60,1.1,200,0.000347399240126833,-2.46375203132629,0.881173968315124,1,,,,,,,,,,,,,,,,
,3739960712.18986,117.62260055542,499.652862548828,,,6,,,,31.6118758000877,,,10,,,,,,,,,,,,,,,,,,,,,,117.519439697266,117.725761413574,499.652862548828,499.652862548828,,,10.1137590408325,-99999999,1,0,0,0,0.0263214111328125,30.3030319213867,2,1,1,117.725761413574,0,3154122144,117.617102305094,,,0.00745195270528373,0.000360396398062087,0.00745216759271064,0.000360330739248235,0.967318952083588,0.974576830863953,31.6912078857422,0.186543509364128,60,1.1,200,-0.000798331864643842,-2.44741249084473,0.874842584133148,1,,,,,,,,,,,,,,,,
,3739960757.34716,119.126438140869,499.652862548828,,,6,,,,31.6118758000877,,,10,,,,,,,,,,,,,,,,,,,,,,119.022682189941,119.203460693359,499.652862548828,499.652862548828,,,10.1484088897705,-99999999,1,0,0,0,0.0347137451171875,30.3030319213867,2,1,1,119.230194091797,0,3154122176,119.118061065674,,,0.00740967972802999,0.00035835273318883,0.00740990433559032,0.000358287131177264,0.967230260372162,0.974555313587189,31.6916599273682,0.186565339565277,60,1.1,200,0.000237520231166854,-2.43551278114319,0.87078207731247,1,,,,,,,,,,,,,,,,
,3739960802.21449,120.618389129639,499.652862548828,,,6,,,,31.6168764535537,,,10,,,,,,,,,,,,,,,,,,,,,,120.521514892578,120.684303283691,499.652862548828,499.652862548828,,,10.1718635559082,-99999999,1,0,0,0,0.029754638671875,30.3030319213867,2,1,1,120.715263366699,0,3154121856,120.599371337891,,,0.00737369461648659,0.00035660336728572,0.0073738109765602,0.000356539714398457,0.968021392822266,0.974813401699066,31.6930027008057,0.186557590961456,60,1.1,200,-0.000109464861452579,-2.42268037796021,0.865434110164642,1,,,,,,,,,,,,,,,,
,3739960847.77068,122.118537902832,499.652862548828,,,6,,,,31.6168764535537,,,10,,,,,,,,,,,,,,,,,,,,,,122.017417907715,122.191307067871,499.652862548828,499.652862548828,,,10.210241317749,-99999999,1,0,0,0,0.0270843505859375,30.3030319213867,2,1,1,122.219657897949,0,3154122048,122.099537658691,,,0.00734406779075763,0.000355173944655699,0.00734422782730334,0.000355109412807483,0.967721521854401,0.974795937538147,31.6947917938232,0.186562284827232,60,1.1,200,0.000396068207919598,-2.41508173942566,0.859770476818085,1,,,,,,,,,,,,,,,,
,3739960892.91745,123.630504608154,499.652862548828,,,6,,,,31.6168764535537,,,10,,,,,,,,,,,,,,,,,,,,,,123.523002624512,123.700286865234,499.652862548828,499.652862548828,,,10.2239875793457,-99999999,1,0,0,0,0.0223541259765625,30.3030319213867,2,1,1,123.738006591797,0,3154121952,123.61110534668,,,0.00733338264148794,0.000354658538904507,0.00733355098989498,0.000354593027348054,0.967598974704742,0.974804878234863,31.6955833435059,0.186548322439194,60,1.1,200,0.000117702431452926,-2.40980386734009,0.86205130815506,1,,,,,,,,,,,,,,,,
,3739960937.941,125.126377105713,499.652862548828,,,6,,,,31.6168764535537,,,10,,,,,,,,,,,,,,,,,,,,,,125.022048950195,125.199913024902,499.652862548828,499.652862548828,,,10.2444925308228,-99999999,1,0,0,0,0.0260162353515625,30.3030319213867,2,1,1,125.23070526123,0,3154122240,125.104177856445,,,0.00734838273413139,0.000355388285948352,0.00734860114718315,0.000355320250988087,0.967246651649475,0.974884271621704,31.6981067657471,0.186550468206406,60,1.1,200,0.00110115960706025,-2.41435360908508,0.860941350460052,1,,,,,,,,,,,,,,,,
,3739960983.29364,126.624660491943,499.652862548828,,,6,,,,31.6218961889371,,,10,,,,,,,,,,,,,,,,,,,,,,126.523834228516,126.684585571289,499.652862548828,499.652862548828,,,10.2567415237427,-99999999,1,0,0,0,0.0173187255859375,30.3030319213867,2,1,1,126.725486755371,0,3154122080,126.60132598877,,,0.00742644774475553,0.000359155645619911,0.00742660589152694,0.000359090372071214,0.967925369739532,0.975039780139923,31.6997241973877,0.186552733182907,60,1.1,200,0.001094730803743,-2.44066190719604,0.869803607463837,1,,,,,,,,,,,,,,,,
,3739961028.36511,128.123390197754,499.652862548828,,,6,,,,31.6218961889371,,,10,,,,,,,,,,,,,,,,,,,,,,128.025344848633,128.198089599609,499.652862548828,499.652862548828,,,10.269832611084,-99999999,1,0,0,0,0.0257110595703125,30.3030319213867,2,1,1,128.221435546875,0,3154122016,128.112505594889,,,0.00765654631644529,0.000370290881654762,0.00765677598427755,0.000370220963220141,0.967316567897797,0.974882066249847,31.7026958465576,0.186567410826683,60,1.1,200,-0.000564167217817158,-2.52127814292908,0.900959730148315,1,,,,,,,,,,,,,,,,
,3739961073.56208,129.634742736816,499.652862548828,,,6,,,,31.6218961889371,,,10,,,,,,,,,,,,,,,,,,,,,,129.525894165039,129.719100952148,499.652862548828,499.652862548828,,,10.2798595428467,-99999999,1,0,0,0,0.0263214111328125,30.3030319213867,2,1,1,129.743591308594,0,3154121888,129.628751118978,,,0.00881150263102541,0.000426204678582691,0.00881229093770502,0.000426109461851103,0.9634610414505,0.973355054855347,31.7185230255127,0.186573371291161,60,1.1,200,-0.00217329734005034,-2.96715712547302,1.05108618736267,1,,,,,,,,,,,,,,,,
,3739961118.66635,131.12084197998,499.652862548828,,,6,,,,31.6218961889371,,,10,,,,,,,,,,,,,,,,,,,,,,131.021469116211,131.18815612793,499.652862548828,499.652862548828,,,10.2864761352539,-99999999,1,0,0,0,0.026702880859375,30.3030319213867,2,1,1,131.22021484375,0,3154121760,131.107757568359,,,0.0106551564946807,0.000515310513721405,0.0106551944065671,0.000515226086947467,0.9673952460289,0.973008275032044,31.6925659179687,0.18657486140728,60,1.1,200,-0.00257033947855234,-3.5559983253479,1.27997326850891,1,,,,,,,,,,,,,,,,
,3739961163.56374,132.62589263916,499.652862548828,,,6,,,,31.6269152906091,,,10,,,,,,,,,,,,,,,,,,,,,,132.52571105957,132.72053527832,499.652862548828,499.652862548828,,,10.2985410690308,-99999999,1,0,0,0,0.0238037109375,30.3030319213867,2,1,1,132.72607421875,0,3154121952,132.619644165039,,,0.00918170996715177,0.00044410731166228,0.00918133443898374,0.000444073040390907,0.963697791099548,0.96470981836319,31.6598014831543,0.186590656638145,60,1.1,200,0.00711413659155369,-3.19293928146362,1.0552579164505,1,,,,,,,,,,,,,,,,
,3739961208.88466,134.126281738281,499.652862548828,,,6,,,,31.6269152906091,,,10,,,,,,,,,,,,,,,,,,,,,,134.027862548828,134.224700927734,499.652862548828,499.652862548828,,,10.3066463470459,-99999999,1,0,0,0,0.0252532958984375,30.3030319213867,2,1,1,134.224700927734,0,3154122048,134.129475911458,,,0.00602518885050384,0.000291468597684982,0.00602494616135143,0.000291446420980668,0.960266470909119,0.961176753044128,31.6595897674561,0.186630070209503,60,1.1,200,0.00494491681456566,-2.04511213302612,0.724770188331604,1,,,,,,,,,,,,,,,,
,3739961253.47063,135.62712097168,499.652862548828,,,6,,,,31.6269152906091,,,10,,,,,,,,,,,,,,,,,,,,,,135.521133422852,135.70263671875,499.652862548828,499.652862548828,,,10.3126001358032,-99999999,1,0,0,0,0.0244903564453125,30.3030319213867,2,1,1,135.733108520508,0,3154122080,135.614471435547,,,0.00387151408887601,0.000187275418493058,0.00387135590232829,0.000187260890150938,0.961517632007599,0.962482571601868,31.6599979400635,0.186591953039169,60,1.1,200,0.00224781781435013,-1.32859826087952,0.448341846466064,1,,,,,,,,,,,,,,,,
,3739961302.87383,137.259475708008,499.652862548828,,,6,,,,31.6319197636847,,,10,,,,,,,,,,,,,,,,,,,,,,137.160705566406,137.335922241211,499.652862548828,499.652862548828,,,10.3105421066284,-99999999,1,0,0,0,0.0255584716796875,30.3030319213867,2,1,1,137.358245849609,0,3154122176,137.252014160156,,,0.00247378829209396,0.000119626437117743,0.00247379923081281,0.000119621259484291,0.970703899860382,0.97237879037857,31.6696109771729,0.186500281095505,60,1.1,200,0.00069960969267413,-0.858874559402466,0.270122617483139,1,,,,,,,,,,,,,,,,
,3739961343.67469,138.626113891602,499.652862548828,,,6,,,,31.6319197636847,,,10,,,,,,,,,,,,,,,,,,,,,,138.521667480469,138.703277587891,499.652862548828,499.652862548828,,,10.3233976364136,-99999999,1,0,0,0,0.024261474609375,30.3030319213867,2,1,1,138.730560302734,0,3154121952,138.615386962891,,,0.0018813858654278,9.09901985112194E-5,0.00188131046372582,9.09831102259109E-5,0.966860353946686,0.968020915985107,31.6654930114746,0.186586111783981,60,1.1,200,0.00144998857285827,-0.661098182201385,0.19497999548912,1,,,,,,,,,,,,,,,,
,3739961389.48364,140.124626159668,499.652862548828,,,6,,,,31.6319197636847,,,10,,,,,,,,,,,,,,,,,,,,,,140.02018737793,140.202972412109,499.652862548828,499.652862548828,,,10.3424062728882,-99999999,1,0,0,0,0.025177001953125,30.3030319213867,2,1,1,140.229064941406,0,3154122144,140.112728881836,,,0.00143828926041803,6.95567767236266E-5,0.00143822936336118,6.95506842566387E-5,0.968536496162415,0.970030963420868,31.6689109802246,0.186551943421364,60,1.1,200,0.000473510473966599,-0.513226807117462,0.139103844761848,1,,,,,,,,,,,,,,,,
,3739961434.20643,141.631965637207,499.652862548828,,,6,,,,31.6319197636847,,,10,,,,,,,,,,,,,,,,,,,,,,141.524154663086,141.715255737305,499.652862548828,499.652862548828,,,10.3573350906372,-99999999,1,0,0,0,0.0231170654296875,30.3030319213867,2,1,1,141.739776611328,0,3154122112,141.626647949219,,,0.00114746556691628,5.54910834369073E-5,0.00114741870381226,5.5486006301433E-5,0.969238638877869,0.970930457115173,31.6707592010498,0.186567664146423,60,1.1,200,0.000463024800410494,-0.417489290237427,0.102280236780643,1,,,,,,,,,,,,,,,,
,3739961479.58869,143.140022277832,499.652862548828,,,6,,,,31.6369282724374,,,10,,,,,,,,,,,,,,,,,,,,,,143.033432006836,143.20915222168,499.652862548828,499.652862548828,,,10.3773469924927,-99999999,1,0,0,0,0.02685546875,30.3030319213867,2,1,1,143.246612548828,0,3154122368,143.122100830078,,,0.000919182280685526,4.44426954199969E-5,0.000919198194415497,4.44405037099098E-5,0.976447641849518,0.979469060897827,31.6814384460449,0.186470985412598,60,1.1,200,-8.9197070337832E-5,-0.341490387916565,0.0737945809960365,1,,,,,,,,,,,,,,,,
,3739961524.15092,144.608497619629,499.652862548828,,,6,,,,31.6369282724374,,,10,,,,,,,,,,,,,,,,,,,,,,144.506683349609,144.686904907227,499.652862548828,499.652862548828,,,10.3896923065186,-99999999,1,0,0,0,0.0252532958984375,30.3030319213867,2,1,1,144.710311889648,0,3154122048,144.599237060547,,,0.000789869614747751,3.81958148742767E-5,0.000789838584850798,3.81924317730178E-5,0.971035003662109,0.972788512706757,31.6752223968506,0.186546295881271,60,1.1,200,0.000262628338532522,-0.298947334289551,0.057460967451334,1,,,,,,,,,,,,,,,,
,3739961569.75639,146.123519897461,499.652862548828,,,6,,,,31.6369282724374,,,10,,,,,,,,,,,,,,,,,,,,,,146.022903442383,146.193466186523,499.652862548828,499.652862548828,,,10.4031343460083,-99999999,1,0,0,0,0.027313232421875,30.3030319213867,2,1,1,146.224136352539,0,3154122144,146.102670288086,,,0.000676941037635155,3.27347503602209E-5,0.000676913113773869,3.27315895001021E-5,0.971227407455444,0.973217129707336,31.6774845123291,0.186552971601486,60,1.1,200,0.000217804219573736,-0.261540800333023,0.0434818156063557,1,,,,,,,,,,,,,,,,
,3739961614.69054,147.622314453125,499.652862548828,,,6,,,,31.6369282724374,,,10,,,,,,,,,,,,,,,,,,,,,,147.520080566406,147.697280883789,499.652862548828,499.652862548828,,,10.4076013565063,-99999999,1,0,0,0,0.02288818359375,30.3030319213867,2,1,1,147.724548339844,0,3154122272,147.605960083008,,,0.000588498034932339,2.84577430882568E-5,0.000588474696639792,2.84549483486451E-5,0.971423447132111,0.973550021648407,31.6786422729492,0.186538979411125,60,1.1,200,0.000272127857897431,-0.232902556657791,0.0325056202709675,1,,,,,,,,,,,,,,,,
,3739961659.21843,149.129013061523,499.652862548828,,,6,,,,31.6419309004964,,,10,,,,,,,,,,,,,,,,,,,,,,149.025314331055,149.195129394531,499.652862548828,499.652862548828,,,10.4101305007935,-99999999,1,0,0,0,0.0255584716796875,30.3030319213867,2,1,1,149.232711791992,0,3154122144,149.10735168457,,,0.000516476490939478,2.49747052133049E-5,0.00051645530779577,2.49724610591449E-5,0.971881806850433,0.973674833774567,31.6800231933594,0.18654265999794,60,1.1,200,0.000333254312863573,-0.209408864378929,0.023239703848958,1,,,,,,,,,,,,,,,,
,3739961754.87408,149.931053161621,499.652862548828,,,6,,,,31.6419309004964,,,10,,,,,,,,,,,,,,,,,,,,,,149.926467895508,149.935638427734,499.652862548828,499.652862548828,,,10.4239320755005,-99999999,1,0,0,0,0.023956298828125,30.3030319213867,1,1,1,149.935638427734,0,3154122144,149.931561787923,,,0.000478588411238935,2.3139194102111E-5,0.000478601629907434,2.31379928305422E-5,0.97769820690155,0.981605291366577,31.6905136108398,0.186465233564377,60,1.1,200,-6.55513431411236E-5,-0.197171807289124,0.018121974542737,1,,,,,,,,,,,,,,,,
,3739961836.38981,155.445014953613,499.652862548828,,,6,,,,31.6470005847981,,,10,,,,,,,,,,,,,,,,,,,,,,155.129730224609,155.658813476562,499.652862548828,499.652862548828,,,10.4667482376099,-99999999,1,0,0,0,0.02716064453125,30.3030319213867,2,1,1,155.760299682617,0,3154122208,155.398416137695,,,0.000331329312023071,1.60203692274999E-5,0.000331337528995313,1.60195117825933E-5,0.975105762481689,0.978478848934174,31.6951694488525,0.186470597982407,60,1.1,200,8.36326944408938E-5,-0.150204539299011,-2.51084584306227E-5,1,,,,,,,,,,,,,,,,
,3739961910.16748,162.858215332031,499.652862548828,,,6,,,,31.652000798035,,,10,,,,,,,,,,,,,,,,,,,,,,162.562622070313,163.075225830078,499.652862548828,499.652862548828,,,10.5181636810303,-99999999,1,0,0,0,0.0183868408203125,30.3030319213867,2,1,1,163.15380859375,0,3154122176,162.82102355957,,,0.00022895177352688,1.10716977218425E-5,0.000228942766103294,1.10707115662705E-5,0.97027313709259,0.971994519233704,31.6903457641602,0.186548069119453,60,1.1,200,7.17170623829588E-5,-0.116319067776203,-0.0126990685239434,1,,,,,,,,,,,,,,,,
,3739961988.93808,170.734954833984,499.652862548828,,,6,,,,31.6620190058698,,,1,,,,,,,,,,,,,,,,,,,,,,170.119216918945,171.258865356445,499.652862548828,499.652862548828,,,10.5677442550659,-99999999,1,0,0,0,0.0249481201171875,30.3030319213867,2,1,1,171.350692749023,0,3154122208,170.688272649592,,,0.000161519762064391,7.81019716589744E-6,0.000161520785913351,7.80979994488326E-6,0.973011136054993,0.975219428539276,31.7030410766602,0.186477333307266,60,1.1,200,0.000115418821224011,-0.948595285415649,-0.0208147633820772,1,,,,,,,,,,,,,,,,
,3739962060.65766,177.882804870605,499.652862548828,,,6,,,,31.6670193139434,,,1,,,,,,,,,,,,,,,,,,,,,,177.575576782227,178.080169677734,499.652862548828,499.652862548828,,,10.6127481460571,-99999999,1,0,0,0,0.02593994140625,30.3030319213867,2,1,1,178.199066162109,0,3154122240,177.805737304688,,,0.000128593603385818,6.2191221077874E-6,0.000128588334638737,6.21865702814295E-6,0.967354714870453,0.968406319618225,31.6985263824463,0.186559736728668,60,1.1,200,0.000384088372811675,-0.836851835250855,-0.254739850759506,1,,,,,,,,,,,,,,,,
,3739962141.74739,185.911422729492,499.652862548828,,,6,,,,31.6770404163764,,,1,,,,,,,,,,,,,,,,,,,,,,185.329650878906,186.424285888672,499.652862548828,499.652862548828,,,10.6556053161621,-99999999,1,0,0,0,0.0183868408203125,30.3030319213867,2,1,1,186.493194580078,0,3154122144,185.879760742187,,,0.000100662046927497,4.86856114866094E-6,0.000100663333576895,4.86834719043488E-6,0.965627074241638,0.967317223548889,31.7177429199219,0.186525762081146,60,1.1,200,-0.00030297419289127,-0.749323070049286,-0.0289523620158434,1,,,,,,,,,,,,,,,,
,3739962211.94121,192.862663269043,499.652862548828,,,6,,,,31.68205914472,,,1,,,,,,,,,,,,,,,,,,,,,,192.564926147461,193.083541870117,499.652862548828,499.652862548828,,,10.699387550354,-99999999,1,0,0,0,0.02166748046875,30.3030319213867,2,1,1,193.160400390625,0,3154122176,192.847254435221,,,8.52615983696152E-5,4.12464038323035E-6,8.5258205610562E-5,4.12433136941354E-6,0.959607481956482,0.960485279560089,31.7140483856201,0.186617121100426,60,1.1,200,0.000370833382476121,-0.698328971862793,-0.310545891523361,1,,,,,,,,,,,,,,,,
,3739962290.28915,200.71395111084,499.652862548828,,,6,,,,31.6920750503824,,,1,,,,,,,,,,,,,,,,,,,,,,200.113296508789,201.220352172852,499.652862548828,499.652862548828,,,10.7634496688843,-99999999,1,0,0,0,0.0206756591796875,30.3030319213867,2,1,1,201.314605712891,0,3154121952,200.685360717773,,,7.02661891369655E-5,3.39979900785883E-6,7.02668483900401E-5,3.39968002862087E-6,0.955578446388245,0.956586956977844,31.7279262542725,0.186602830886841,60,1.1,200,-3.89705346606206E-5,-0.652419090270996,-0.0330107696354389,1,,,,,,,,,,,,,,,,
,3739962365.95494,208.204177856445,499.652862548828,,,6,,,,31.7020954362299,,,1,,,,,,,,,,,,,,,,,,,,,,207.617568969727,208.730682373047,499.652862548828,499.652862548828,,,10.8069887161255,-99999999,1,0,0,0,0.022735595703125,30.3030319213867,2,1,1,208.790786743164,0,3154121888,208.193388505415,,,6.03621389262653E-5,2.92145512150998E-6,6.03624933327393E-5,2.92137718944486E-6,0.94940710067749,0.950052917003632,31.7327194213867,0.186656475067139,60,1.1,200,-9.22661056392826E-5,-0.62065601348877,-0.0344252623617649,1,,,,,,,,,,,,,,,,
,3739962441.71914,215.768402099609,499.652862548828,,,6,,,,31.7121006555585,,,1,,,,,,,,,,,,,,,,,,,,,,215.153350830078,216.270248413086,499.652862548828,499.652862548828,,,10.8469905853271,-99999999,1,0,0,0,0.0289154052734375,30.3030319213867,2,1,1,216.383453369141,0,3154122112,215.737031555176,,,5.229966871085E-5,2.53205406343037E-6,5.22998662206255E-5,2.5319969582192E-6,0.943438053131103,0.943903982639313,31.7395820617676,0.186710357666016,60,1.1,200,0.000177444846485741,-0.595515489578247,-0.0355038829147816,1,,,,,,,,,,,,,,,,
,3739962516.86834,223.234962463379,499.652862548828,,,6,,,,31.7221424977089,,,1,,,,,,,,,,,,,,,,,,,,,,222.631759643555,223.751434326172,499.652862548828,499.652862548828,,,10.8849363327026,-99999999,1,0,0,0,0.0196075439453125,30.3030319213867,2,1,1,223.838165283203,0,3154122080,223.194960021973,,,4.59705372485356E-5,2.22665065875483E-6,4.59707327556642E-5,2.22660995940888E-6,0.935890138149261,0.936241090297699,31.747501373291,0.186794087290764,60,1.1,200,-3.14362441713456E-5,-0.575581669807434,-0.0363829769194126,1,,,,,,,,,,,,,,,,
,3739962590.97045,230.684219360352,499.652862548828,,,6,,,,31.7324791639134,,,1,,,,,,,,,,,,,,,,,,,,,,230.103713989258,231.170654296875,499.652862548828,499.652862548828,,,10.8812446594238,-99999999,1,0,0,0,0.0213623046875,30.3030319213867,2,1,1,231.264724731445,0,3154122304,230.634030151367,,,4.08710217447843E-5,1.9807901418647E-6,4.08709986091772E-5,1.98077062874735E-6,0.9274862408638,0.927613735198975,31.7487087249756,0.186880871653557,60,1.1,200,0.000134249028633349,-0.562487423419952,-0.037379864603281,1,,,,,,,,,,,,,,,,
,3739962663.00122,237.888801574707,499.652862548828,,,6,,,,31.7425060593724,,,1,,,,,,,,,,,,,,,,,,,,,,237.588043212891,238.128662109375,499.652862548828,499.652862548828,,,10.855489730835,-99999999,1,0,0,0,0.022735595703125,30.3030319213867,2,1,1,238.207077026367,0,3154122240,237.861819458008,,,3.69791281183407E-5,1.79315348870318E-6,3.69785589019971E-5,1.79312249807162E-6,0.920328497886658,0.920352041721344,31.7498149871826,0.187059819698334,60,1.1,200,0.000308011251036078,-0.550863325595856,-0.378937840461731,1,,,,,,,,,,,,,,,,
,3739962741.66265,245.737648010254,499.652862548828,,,6,,,,31.7575888927741,,,1,,,,,,,,,,,,,,,,,,,,,,245.113647460938,246.274459838867,499.652862548828,499.652862548828,,,10.9054298400879,-99999999,1,0,0,0,0.020904541015625,30.3030319213867,2,1,1,246.36164855957,0,3154122176,245.699969482422,,,3.26523766021948E-5,1.5853853089414E-6,3.26523406454179E-5,1.58537787635617E-6,0.905643343925476,0.905681073665619,31.7676048278809,0.187244161963463,60,1.1,200,-0.000348301109625027,-0.539745807647705,-0.0387658961117268,1,,,,,,,,,,,,,,,,
,3739962817.16346,253.23365020752,499.652862548828,,,6,,,,31.7684596775914,,,1,,,,,,,,,,,,,,,,,,,,,,252.625015258789,253.84228515625,499.652862548828,499.652862548828,,,10.9749546051025,-99999999,1,0,0,0,0.011749267578125,30.3030319213867,2,1,1,253.84228515625,0,3154121728,253.245089444247,,,2.94217562136569E-5,1.42944811911189E-6,2.9421745850948E-5,1.42944754358503E-6,0.899111449718475,0.899111926555634,31.7696437835693,0.187356546521187,60,1.1,200,-0.000155393136083148,-0.5315220952034,-0.0394461341202259,1,,,,,,,,,,,,,,,,
,3739962894.69231,260.737060546875,499.652862548828,,,6,,,,31.779291671725,,,1,,,,,,,,,,,,,,,,,,,,,,260.113311767578,261.285949707031,499.652862548828,499.652862548828,,,11.0188646316528,-99999999,1,0,0,0,0.016326904296875,30.3030319213867,2,1,1,261.360809326172,0,3154122176,260.732829700817,,,2.67856159040056E-5,1.30285415505024E-6,2.67855762846953E-5,1.30285209988661E-6,0.888508796691895,0.888509690761566,31.7809410095215,0.187588855624199,60,1.1,200,0.000493022671435028,-0.520533740520477,-0.0395574457943439,1,,,,,,,,,,,,,,,,
,3739962969.93773,268.390625,499.652862548828,,,6,,,,31.7949510157942,,,1,,,,,,,,,,,,,,,,,,,,,,267.764862060547,268.973785400391,499.652862548828,499.652862548828,,,11.0704517364502,-99999999,1,0,0,0,0.02166748046875,30.3030319213867,2,1,1,269.037933349609,0,3154122240,268.390458540483,,,2.45472656735285E-5,1.19471189196866E-6,2.45474893841793E-5,1.19471962364058E-6,0.883215725421906,0.883238017559052,31.7864189147949,0.187700316309929,60,1.1,200,-0.000220341491512954,-0.514155805110931,-0.0399260260164738,1,,,,,,,,,,,,,,,,
,3739963042.27937,275.766571044922,499.652862548828,,,6,,,,31.8064572469524,,,1,,,,,,,,,,,,,,,,,,,,,,275.119812011719,276.393493652344,499.652862548828,499.652862548828,,,11.1021614074707,-99999999,1,0,0,0,0.0206756591796875,30.3030319213867,2,1,1,276.413330078125,0,3154121792,275.778278697621,,,2.21631869233793E-5,1.08108244813647E-6,2.21634285502474E-5,1.08108951265164E-6,0.865761637687683,0.865793585777283,31.7955513000488,0.188111901283264,60,1.1,200,-0.000134607747895643,-0.511944055557251,-0.0406844206154346,1,,,,,,,,,,,,,,,,
,3739963121.21722,283.499572753906,499.652862548828,,,6,,,,31.8215485675547,,,1,,,,,,,,,,,,,,,,,,,,,,282.910095214844,284.00390625,499.652862548828,499.652862548828,,,11.1567306518555,-99999999,1,0,0,0,0.00335693359375,30.3030319213867,2,1,1,284.089050292969,0,3154122048,283.434573364258,,,2.04533568368311E-5,9.98372211246632E-7,2.04540102811018E-5,9.98381807264923E-7,0.860787630081177,0.860945045948029,31.7969303131103,0.188229516148567,60,1.1,200,0.000116840317787137,-0.511467456817627,-0.0414593555033207,1,,,,,,,,,,,,,,,,
,3739963193.68558,290.728927612305,499.652862548828,,,6,,,,31.8334318987368,,,1,,,,,,,,,,,,,,,,,,,,,,290.116271972656,291.255126953125,499.652862548828,499.652862548828,,,11.2465181350708,-99999999,1,0,0,0,0.0026702880859375,30.3030319213867,2,1,1,291.341583251953,0,3154122144,290.672893177379,,,1.88101520107302E-5,9.20214893719763E-7,1.88111904064044E-5,9.20220795245479E-7,0.845901489257812,0.846210896968842,31.7972011566162,0.188649848103523,60,1.1,200,0.000196460707229562,-0.50848376750946,-0.0418996848165989,1,,,,,,,,,,,,,,,,
,3739963268.95036,298.120056152344,499.652862548828,,,6,,,,31.8484783462123,,,1,,,,,,,,,,,,,,,,,,,,,,297.601806640625,298.585876464844,499.652862548828,499.652862548828,,,11.3847713470459,-99999999,1,0,0,0,0.0019073486328125,30.3030319213867,2,1,1,298.638305664063,0,3154122048,298.115570068359,,,1.74084891278454E-5,8.54161405519354E-7,1.74093535000094E-5,8.54161417950148E-7,0.828263163566589,0.828543901443481,31.8121509552002,0.189203768968582,60,1.1,200,-0.000332842289935797,-0.506065249443054,-0.042204637080431,1,,,,,,,,,,,,,,,,
,3739963362.24421,299.939483642578,499.652862548828,,,6,,,,31.8484783462123,,,1,,,,,,,,,,,,,,,,,,,,,,299.93603515625,299.943023681641,499.652862548828,499.652862548828,,,11.5455436706543,-99999999,1,0,0,0,0.0019073486328125,30.3030319213867,1,1,1,299.942932128906,0,3154122112,299.940173339844,,,1.7115012077384E-5,8.39411271875872E-7,1.71154640762124E-5,8.39420196624848E-7,0.830640435218811,0.83073091506958,31.8279781341553,0.189127698540688,60,1.1,200,-4.30761792813428E-5,-0.506090641021729,-0.422478795051575,1,,,,,,,,,,,,,,,,